Workbook

Sheet README
B1: Project Budget Calculator
B3: PURPOSE | C3: Calculates the Budgeted balance of each project and phases it over the remaining months of the project.
B5: FORMULAS
B6: Budgeted | C6: Budgeted = Contracted Budget − WIP to date (the sum of WIP logged in months up to and including the Current Month).
B7: Phased Budgeted | C7: Budgeted is spread only over the project months AFTER the Current Month, using that project's phasing weights for those months, renormalised to 1.0.
C8: Phased Budgeted (month k) = Budgeted × weight(k) ÷ Σ weights of remaining months.
B9: Weights | C9: Enter raw weights (e.g. 1,2,2,2,2). They don't need to sum to 1. If a project has no weights at all, every month gets an equal weight.
B10: Example (from the slide) | C10: Contract 10,000. 5 months, weights 1:2:2:2:2. 1,000 of WIP logged in month I (the current month).
C11: → Budgeted = 9,000, phased over months II–V (weights 2:2:2:2 → 25% each) = 2,250 per month.
B13: SHEETS
B14: Projects | C14: Project ∑ table (page 1). Holds the global Current Month field. Add a project by filling in the next empty row. Use the header filter buttons to filter.
B15: Phasing | C15: Raw phasing weights per project, month 1–24 of the project. Also shows the weights normalised to 1.0 over the full duration.
B16: WIP Log | C16: Monthly WIP actuals per project on the calendar timeline. Only months ≤ Current Month count towards WIP to date.
B17: Project Page | C17: Page 2: pick a project from the dropdown to see its details, month-by-month phasing and chart (the "visualize" view).
B18: Timeline | C18: Page 3: Gantt-style view of every project. Each cell shows the WIP actual (≤ Current Month) or the Phased Budgeted (after it).
B19: Aggregator | C19: Page 4: Σ WIP + Σ Phased Budgeted per month against the manual TRM input, with a chart and calendar-year totals.
B20: Phased Budget | C20: Calculation grid (no inputs): Phased Budgeted per project per calendar month.
B22: HOW TO USE
B23: Yellow cells | C23: Key inputs: Current Month, Timeline Start, the TRM row and the project selector.
B24: Blue text | C24: Hard-coded inputs: project fields, weights, WIP amounts. Black text = formulas. Green text = links to another sheet.
B25: Light yellow grids | C25: Input grids on Phasing and WIP Log. Grey cells there are outside the project's duration or window.
B26: Monthly routine | C26: 1) Log the month's WIP on WIP Log. 2) Move Current Month forward one month on Projects. Everything recalculates.
B27: Status column | C27: Projects!N flags problems: WIP above contract, no remaining months left to phase the budget into, missing fields, etc.
B29: LIMITS & ASSUMPTIONS
B30: Capacity | C30: 50 projects, durations up to 24 months, calendar timeline of 36 months from Timeline Start (default Jan 2026 – Dec 2028).
B31: Timeline Start | C31: Change it only before logging WIP: the WIP Log columns are tied to calendar months, so moving the start shifts those columns.
B32: Months | C32: Starting Month and Current Month are compared by year and month only (the day is ignored).
B33: Units | C33: All amounts are in one currency unit (enter 10000 for 10k). No currency symbol is applied.
B34: TRM | C34: Monthly comparison target, entered manually on the Aggregator sheet (per user).
B35: Annual totals | C35: Calendar years (Jan–Dec), WIP actuals + Phased Budgeted.
B36: Source | C36: Logic from "Revenue_Forecast_Calculator.pptx", with the user's clarifications from 2026-10-06.

Sheet Projects
A1: Project ∑ Table
A2: Current Month | C2: 46296 | D2: Months up to and including this month are actuals (WIP). Later months are forecast (Phased Budgeted).
A3: Timeline Start | C3: 46023 | D3: First month of the 36-month calendar timeline. Change it only before logging WIP.
A5: # | B5: Project Name | C5: Engagement Manager | D5: Starting Month | E5: Duration (months) | F5: End Month | G5: Contracted Budget | H5: WIP to Date | I5: Budgeted (Contract − WIP) | J5: Remaining Months | K5: Phased Budgeted – Next Month | L5: Phased Budgeted – Rest of Current Year | M5: Current-Year Forecast (WIP + Phased) | N5: Status
A6: 1 | B6: Example Project (slide) | C6: J. Doe | D6: 46296 | E6: 5 | F6: =IF(OR(D6="",E6=""),"",EDATE(D6,E6-1)) -> 46419 | G6: 10000 | H6: =IF(B6="","",'WIP Log'!C6) -> 1000 | I6: =IF(B6="","",N(G6)-N(H6)) -> 9000 | J6: =IF(OR(B6="",E6=""),"",MAX(0,E6-Phasing!F6+1)) -> 4 | K6: =IF(B6="","",IF(AND(((YEAR(Projects!$C$2)-YEAR(Projects!$C$3))*12+MONTH(Projects!$C$2)-MONTH(Projects!$C$3)+1)+1>=1,((YEAR(Projects!$C$2)-YEAR(Projects!$C$3))*12+MONTH(Projects!$C$2)-MONTH(Projects!$C$3)+1)+1<=36),INDEX('Phased Budget'!$H6:$AQ6,((YEAR(Projects!$C$2)-YEAR(Projects!$C$3))*12+MONTH(Projects!$C$2)-MONTH(Projects!$C$3)+1)+1),0)) -> 2250 | L6: =IF(B6="","",SUMPRODUCT('Phased Budget'!$H6:$AQ6*(YEAR('Phased Budget'!$H$5:$AQ$5)=YEAR(Projects!$C$2)))) -> 4500 | M6: =IF(B6="","",SUMPRODUCT('WIP Log'!$D6:$AM6*('WIP Log'!$D$5:$AM$5<=Projects!$C$2)*(YEAR('WIP Log'!$D$5:$AM$5)=YEAR(Projects!$C$2)))+L6) -> 5500 | N6: =IF(B6="","",IF(OR(D6="",E6="",G6=""),"Missing start / duration / contract",IF(OR(E6<1,E6>24),"Duration must be 1–24",IF(I6<0,"WIP exceeds contract",IF(AND(J6=0,I6<>0),"Budget not phased: no remaining months",IF(AND(J6>0,Phasing!G6=0,I6<>0),"Budget not phased: remaining weights are 0",IF(OR(D6<Projects!$C$3,F6>EDATE(Projects!$C$3,35)),"Partly outside timeline",IF(Phasing!H6=0,"OK","Weights entered beyond duration (ignored)")))))))) -> OK
A7: 2 | F7: =IF(OR(D7="",E7=""),"",EDATE(D7,E7-1)) | H7: =IF(B7="","",'WIP Log'!C7) | I7: =IF(B7="","",N(G7)-N(H7)) | J7: =IF(OR(B7="",E7=""),"",MAX(0,E7-Phasing!F7+1)) | K7: =IF(B7="","",IF(AND(((YEAR(Projects!$C$2)-YEAR(Projects!$C$3))*12+MONTH(Projects!$C$2)-MONTH(Projects!$C$3)+1)+1>=1,((YEAR(Projects!$C$2)-YEAR(Projects!$C$3))*12+MONTH(Projects!$C$2)-MONTH(Projects!$C$3)+1)+1<=36),INDEX('Phased Budget'!$H7:$AQ7,((YEAR(Projects!$C$2)-YEAR(Projects!$C$3))*12+MONTH(Projects!$C$2)-MONTH(Projects!$C$3)+1)+1),0)) | L7: =IF(B7="","",SUMPRODUCT('Phased Budget'!$H7:$AQ7*(YEAR('Phased Budget'!$H$5:$AQ$5)=YEAR(Projects!$C$2)))) | M7: =IF(B7="","",SUMPRODUCT('WIP Log'!$D7:$AM7*('WIP Log'!$D$5:$AM$5<=Projects!$C$2)*(YEAR('WIP Log'!$D$5:$AM$5)=YEAR(Projects!$C$2)))+L7) | N7: =IF(B7="","",IF(OR(D7="",E7="",G7=""),"Missing start / duration / contract",IF(OR(E7<1,E7>24),"Duration must be 1–24",IF(I7<0,"WIP exceeds contract",IF(AND(J7=0,I7<>0),"Budget not phased: no remaining months",IF(AND(J7>0,Phasing!G7=0,I7<>0),"Budget not phased: remaining weights are 0",IF(OR(D7<Projects!$C$3,F7>EDATE(Projects!$C$3,35)),"Partly outside timeline",IF(Phasing!H7=0,"OK","Weights entered beyond duration (ignored)"))))))))
A8: 3 | F8: =IF(OR(D8="",E8=""),"",EDATE(D8,E8-1)) | H8: =IF(B8="","",'WIP Log'!C8) | I8: =IF(B8="","",N(G8)-N(H8)) | J8: =IF(OR(B8="",E8=""),"",MAX(0,E8-Phasing!F8+1)) | K8: =IF(B8="","",IF(AND(((YEAR(Projects!$C$2)-YEAR(Projects!$C$3))*12+MONTH(Projects!$C$2)-MONTH(Projects!$C$3)+1)+1>=1,((YEAR(Projects!$C$2)-YEAR(Projects!$C$3))*12+MONTH(Projects!$C$2)-MONTH(Projects!$C$3)+1)+1<=36),INDEX('Phased Budget'!$H8:$AQ8,((YEAR(Projects!$C$2)-YEAR(Projects!$C$3))*12+MONTH(Projects!$C$2)-MONTH(Projects!$C$3)+1)+1),0)) | L8: =IF(B8="","",SUMPRODUCT('Phased Budget'!$H8:$AQ8*(YEAR('Phased Budget'!$H$5:$AQ$5)=YEAR(Projects!$C$2)))) | M8: =IF(B8="","",SUMPRODUCT('WIP Log'!$D8:$AM8*('WIP Log'!$D$5:$AM$5<=Projects!$C$2)*(YEAR('WIP Log'!$D$5:$AM$5)=YEAR(Projects!$C$2)))+L8) | N8: =IF(B8="","",IF(OR(D8="",E8="",G8=""),"Missing start / duration / contract",IF(OR(E8<1,E8>24),"Duration must be 1–24",IF(I8<0,"WIP exceeds contract",IF(AND(J8=0,I8<>0),"Budget not phased: no remaining months",IF(AND(J8>0,Phasing!G8=0,I8<>0),"Budget not phased: remaining weights are 0",IF(OR(D8<Projects!$C$3,F8>EDATE(Projects!$C$3,35)),"Partly outside timeline",IF(Phasing!H8=0,"OK","Weights entered beyond duration (ignored)"))))))))
A9: 4 | F9: =IF(OR(D9="",E9=""),"",EDATE(D9,E9-1)) | H9: =IF(B9="","",'WIP Log'!C9) | I9: =IF(B9="","",N(G9)-N(H9)) | J9: =IF(OR(B9="",E9=""),"",MAX(0,E9-Phasing!F9+1)) | K9: =IF(B9="","",IF(AND(((YEAR(Projects!$C$2)-YEAR(Projects!$C$3))*12+MONTH(Projects!$C$2)-MONTH(Projects!$C$3)+1)+1>=1,((YEAR(Projects!$C$2)-YEAR(Projects!$C$3))*12+MONTH(Projects!$C$2)-MONTH(Projects!$C$3)+1)+1<=36),INDEX('Phased Budget'!$H9:$AQ9,((YEAR(Projects!$C$2)-YEAR(Projects!$C$3))*12+MONTH(Projects!$C$2)-MONTH(Projects!$C$3)+1)+1),0)) | L9: =IF(B9="","",SUMPRODUCT('Phased Budget'!$H9:$AQ9*(YEAR('Phased Budget'!$H$5:$AQ$5)=YEAR(Projects!$C$2)))) | M9: =IF(B9="","",SUMPRODUCT('WIP Log'!$D9:$AM9*('WIP Log'!$D$5:$AM$5<=Projects!$C$2)*(YEAR('WIP Log'!$D$5:$AM$5)=YEAR(Projects!$C$2)))+L9) | N9: =IF(B9="","",IF(OR(D9="",E9="",G9=""),"Missing start / duration / contract",IF(OR(E9<1,E9>24),"Duration must be 1–24",IF(I9<0,"WIP exceeds contract",IF(AND(J9=0,I9<>0),"Budget not phased: no remaining months",IF(AND(J9>0,Phasing!G9=0,I9<>0),"Budget not phased: remaining weights are 0",IF(OR(D9<Projects!$C$3,F9>EDATE(Projects!$C$3,35)),"Partly outside timeline",IF(Phasing!H9=0,"OK","Weights entered beyond duration (ignored)"))))))))
A10: 5 | F10: =IF(OR(D10="",E10=""),"",EDATE(D10,E10-1)) | H10: =IF(B10="","",'WIP Log'!C10) | I10: =IF(B10="","",N(G10)-N(H10)) | J10: =IF(OR(B10="",E10=""),"",MAX(0,E10-Phasing!F10+1)) | K10: =IF(B10="","",IF(AND(((YEAR(Projects!$C$2)-YEAR(Projects!$C$3))*12+MONTH(Projects!$C$2)-MONTH(Projects!$C$3)+1)+1>=1,((YEAR(Projects!$C$2)-YEAR(Projects!$C$3))*12+MONTH(Projects!$C$2)-MONTH(Projects!$C$3)+1)+1<=36),INDEX('Phased Budget'!$H10:$AQ10,((YEAR(Projects!$C$2)-YEAR(Projects!$C$3))*12+MONTH(Projects!$C$2)-MONTH(Projects!$C$3)+1)+1),0)) | L10: =IF(B10="","",SUMPRODUCT('Phased Budget'!$H10:$AQ10*(YEAR('Phased Budget'!$H$5:$AQ$5)=YEAR(Projects!$C$2)))) | M10: =IF(B10="","",SUMPRODUCT('WIP Log'!$D10:$AM10*('WIP Log'!$D$5:$AM$5<=Projects!$C$2)*(YEAR('WIP Log'!$D$5:$AM$5)=YEAR(Projects!$C$2)))+L10) | N10: =IF(B10="","",IF(OR(D10="",E10="",G10=""),"Missing start / duration / contract",IF(OR(E10<1,E10>24),"Duration must be 1–24",IF(I10<0,"WIP exceeds contract",IF(AND(J10=0,I10<>0),"Budget not phased: no remaining months",IF(AND(J10>0,Phasing!G10=0,I10<>0),"Budget not phased: remaining weights are 0",IF(OR(D10<Projects!$C$3,F10>EDATE(Projects!$C$3,35)),"Partly outside timeline",IF(Phasing!H10=0,"OK","Weights entered beyond duration (ignored)"))))))))
A11: 6 | F11: =IF(OR(D11="",E11=""),"",EDATE(D11,E11-1)) | H11: =IF(B11="","",'WIP Log'!C11) | I11: =IF(B11="","",N(G11)-N(H11)) | J11: =IF(OR(B11="",E11=""),"",MAX(0,E11-Phasing!F11+1)) | K11: =IF(B11="","",IF(AND(((YEAR(Projects!$C$2)-YEAR(Projects!$C$3))*12+MONTH(Projects!$C$2)-MONTH(Projects!$C$3)+1)+1>=1,((YEAR(Projects!$C$2)-YEAR(Projects!$C$3))*12+MONTH(Projects!$C$2)-MONTH(Projects!$C$3)+1)+1<=36),INDEX('Phased Budget'!$H11:$AQ11,((YEAR(Projects!$C$2)-YEAR(Projects!$C$3))*12+MONTH(Projects!$C$2)-MONTH(Projects!$C$3)+1)+1),0)) | L11: =IF(B11="","",SUMPRODUCT('Phased Budget'!$H11:$AQ11*(YEAR('Phased Budget'!$H$5:$AQ$5)=YEAR(Projects!$C$2)))) | M11: =IF(B11="","",SUMPRODUCT('WIP Log'!$D11:$AM11*('WIP Log'!$D$5:$AM$5<=Projects!$C$2)*(YEAR('WIP Log'!$D$5:$AM$5)=YEAR(Projects!$C$2)))+L11) | N11: =IF(B11="","",IF(OR(D11="",E11="",G11=""),"Missing start / duration / contract",IF(OR(E11<1,E11>24),"Duration must be 1–24",IF(I11<0,"WIP exceeds contract",IF(AND(J11=0,I11<>0),"Budget not phased: no remaining months",IF(AND(J11>0,Phasing!G11=0,I11<>0),"Budget not phased: remaining weights are 0",IF(OR(D11<Projects!$C$3,F11>EDATE(Projects!$C$3,35)),"Partly outside timeline",IF(Phasing!H11=0,"OK","Weights entered beyond duration (ignored)"))))))))
A12: 7 | F12: =IF(OR(D12="",E12=""),"",EDATE(D12,E12-1)) | H12: =IF(B12="","",'WIP Log'!C12) | I12: =IF(B12="","",N(G12)-N(H12)) | J12: =IF(OR(B12="",E12=""),"",MAX(0,E12-Phasing!F12+1)) | K12: =IF(B12="","",IF(AND(((YEAR(Projects!$C$2)-YEAR(Projects!$C$3))*12+MONTH(Projects!$C$2)-MONTH(Projects!$C$3)+1)+1>=1,((YEAR(Projects!$C$2)-YEAR(Projects!$C$3))*12+MONTH(Projects!$C$2)-MONTH(Projects!$C$3)+1)+1<=36),INDEX('Phased Budget'!$H12:$AQ12,((YEAR(Projects!$C$2)-YEAR(Projects!$C$3))*12+MONTH(Projects!$C$2)-MONTH(Projects!$C$3)+1)+1),0)) | L12: =IF(B12="","",SUMPRODUCT('Phased Budget'!$H12:$AQ12*(YEAR('Phased Budget'!$H$5:$AQ$5)=YEAR(Projects!$C$2)))) | M12: =IF(B12="","",SUMPRODUCT('WIP Log'!$D12:$AM12*('WIP Log'!$D$5:$AM$5<=Projects!$C$2)*(YEAR('WIP Log'!$D$5:$AM$5)=YEAR(Projects!$C$2)))+L12) | N12: =IF(B12="","",IF(OR(D12="",E12="",G12=""),"Missing start / duration / contract",IF(OR(E12<1,E12>24),"Duration must be 1–24",IF(I12<0,"WIP exceeds contract",IF(AND(J12=0,I12<>0),"Budget not phased: no remaining months",IF(AND(J12>0,Phasing!G12=0,I12<>0),"Budget not phased: remaining weights are 0",IF(OR(D12<Projects!$C$3,F12>EDATE(Projects!$C$3,35)),"Partly outside timeline",IF(Phasing!H12=0,"OK","Weights entered beyond duration (ignored)"))))))))
A13: 8 | F13: =IF(OR(D13="",E13=""),"",EDATE(D13,E13-1)) | H13: =IF(B13="","",'WIP Log'!C13) | I13: =IF(B13="","",N(G13)-N(H13)) | J13: =IF(OR(B13="",E13=""),"",MAX(0,E13-Phasing!F13+1)) | K13: =IF(B13="","",IF(AND(((YEAR(Projects!$C$2)-YEAR(Projects!$C$3))*12+MONTH(Projects!$C$2)-MONTH(Projects!$C$3)+1)+1>=1,((YEAR(Projects!$C$2)-YEAR(Projects!$C$3))*12+MONTH(Projects!$C$2)-MONTH(Projects!$C$3)+1)+1<=36),INDEX('Phased Budget'!$H13:$AQ13,((YEAR(Projects!$C$2)-YEAR(Projects!$C$3))*12+MONTH(Projects!$C$2)-MONTH(Projects!$C$3)+1)+1),0)) | L13: =IF(B13="","",SUMPRODUCT('Phased Budget'!$H13:$AQ13*(YEAR('Phased Budget'!$H$5:$AQ$5)=YEAR(Projects!$C$2)))) | M13: =IF(B13="","",SUMPRODUCT('WIP Log'!$D13:$AM13*('WIP Log'!$D$5:$AM$5<=Projects!$C$2)*(YEAR('WIP Log'!$D$5:$AM$5)=YEAR(Projects!$C$2)))+L13) | N13: =IF(B13="","",IF(OR(D13="",E13="",G13=""),"Missing start / duration / contract",IF(OR(E13<1,E13>24),"Duration must be 1–24",IF(I13<0,"WIP exceeds contract",IF(AND(J13=0,I13<>0),"Budget not phased: no remaining months",IF(AND(J13>0,Phasing!G13=0,I13<>0),"Budget not phased: remaining weights are 0",IF(OR(D13<Projects!$C$3,F13>EDATE(Projects!$C$3,35)),"Partly outside timeline",IF(Phasing!H13=0,"OK","Weights entered beyond duration (ignored)"))))))))
A14: 9 | F14: =IF(OR(D14="",E14=""),"",EDATE(D14,E14-1)) | H14: =IF(B14="","",'WIP Log'!C14) | I14: =IF(B14="","",N(G14)-N(H14)) | J14: =IF(OR(B14="",E14=""),"",MAX(0,E14-Phasing!F14+1)) | K14: =IF(B14="","",IF(AND(((YEAR(Projects!$C$2)-YEAR(Projects!$C$3))*12+MONTH(Projects!$C$2)-MONTH(Projects!$C$3)+1)+1>=1,((YEAR(Projects!$C$2)-YEAR(Projects!$C$3))*12+MONTH(Projects!$C$2)-MONTH(Projects!$C$3)+1)+1<=36),INDEX('Phased Budget'!$H14:$AQ14,((YEAR(Projects!$C$2)-YEAR(Projects!$C$3))*12+MONTH(Projects!$C$2)-MONTH(Projects!$C$3)+1)+1),0)) | L14: =IF(B14="","",SUMPRODUCT('Phased Budget'!$H14:$AQ14*(YEAR('Phased Budget'!$H$5:$AQ$5)=YEAR(Projects!$C$2)))) | M14: =IF(B14="","",SUMPRODUCT('WIP Log'!$D14:$AM14*('WIP Log'!$D$5:$AM$5<=Projects!$C$2)*(YEAR('WIP Log'!$D$5:$AM$5)=YEAR(Projects!$C$2)))+L14) | N14: =IF(B14="","",IF(OR(D14="",E14="",G14=""),"Missing start / duration / contract",IF(OR(E14<1,E14>24),"Duration must be 1–24",IF(I14<0,"WIP exceeds contract",IF(AND(J14=0,I14<>0),"Budget not phased: no remaining months",IF(AND(J14>0,Phasing!G14=0,I14<>0),"Budget not phased: remaining weights are 0",IF(OR(D14<Projects!$C$3,F14>EDATE(Projects!$C$3,35)),"Partly outside timeline",IF(Phasing!H14=0,"OK","Weights entered beyond duration (ignored)"))))))))
A15: 10 | F15: =IF(OR(D15="",E15=""),"",EDATE(D15,E15-1)) | H15: =IF(B15="","",'WIP Log'!C15) | I15: =IF(B15="","",N(G15)-N(H15)) | J15: =IF(OR(B15="",E15=""),"",MAX(0,E15-Phasing!F15+1)) | K15: =IF(B15="","",IF(AND(((YEAR(Projects!$C$2)-YEAR(Projects!$C$3))*12+MONTH(Projects!$C$2)-MONTH(Projects!$C$3)+1)+1>=1,((YEAR(Projects!$C$2)-YEAR(Projects!$C$3))*12+MONTH(Projects!$C$2)-MONTH(Projects!$C$3)+1)+1<=36),INDEX('Phased Budget'!$H15:$AQ15,((YEAR(Projects!$C$2)-YEAR(Projects!$C$3))*12+MONTH(Projects!$C$2)-MONTH(Projects!$C$3)+1)+1),0)) | L15: =IF(B15="","",SUMPRODUCT('Phased Budget'!$H15:$AQ15*(YEAR('Phased Budget'!$H$5:$AQ$5)=YEAR(Projects!$C$2)))) | M15: =IF(B15="","",SUMPRODUCT('WIP Log'!$D15:$AM15*('WIP Log'!$D$5:$AM$5<=Projects!$C$2)*(YEAR('WIP Log'!$D$5:$AM$5)=YEAR(Projects!$C$2)))+L15) | N15: =IF(B15="","",IF(OR(D15="",E15="",G15=""),"Missing start / duration / contract",IF(OR(E15<1,E15>24),"Duration must be 1–24",IF(I15<0,"WIP exceeds contract",IF(AND(J15=0,I15<>0),"Budget not phased: no remaining months",IF(AND(J15>0,Phasing!G15=0,I15<>0),"Budget not phased: remaining weights are 0",IF(OR(D15<Projects!$C$3,F15>EDATE(Projects!$C$3,35)),"Partly outside timeline",IF(Phasing!H15=0,"OK","Weights entered beyond duration (ignored)"))))))))
A16: 11 | F16: =IF(OR(D16="",E16=""),"",EDATE(D16,E16-1)) | H16: =IF(B16="","",'WIP Log'!C16) | I16: =IF(B16="","",N(G16)-N(H16)) | J16: =IF(OR(B16="",E16=""),"",MAX(0,E16-Phasing!F16+1)) | K16: =IF(B16="","",IF(AND(((YEAR(Projects!$C$2)-YEAR(Projects!$C$3))*12+MONTH(Projects!$C$2)-MONTH(Projects!$C$3)+1)+1>=1,((YEAR(Projects!$C$2)-YEAR(Projects!$C$3))*12+MONTH(Projects!$C$2)-MONTH(Projects!$C$3)+1)+1<=36),INDEX('Phased Budget'!$H16:$AQ16,((YEAR(Projects!$C$2)-YEAR(Projects!$C$3))*12+MONTH(Projects!$C$2)-MONTH(Projects!$C$3)+1)+1),0)) | L16: =IF(B16="","",SUMPRODUCT('Phased Budget'!$H16:$AQ16*(YEAR('Phased Budget'!$H$5:$AQ$5)=YEAR(Projects!$C$2)))) | M16: =IF(B16="","",SUMPRODUCT('WIP Log'!$D16:$AM16*('WIP Log'!$D$5:$AM$5<=Projects!$C$2)*(YEAR('WIP Log'!$D$5:$AM$5)=YEAR(Projects!$C$2)))+L16) | N16: =IF(B16="","",IF(OR(D16="",E16="",G16=""),"Missing start / duration / contract",IF(OR(E16<1,E16>24),"Duration must be 1–24",IF(I16<0,"WIP exceeds contract",IF(AND(J16=0,I16<>0),"Budget not phased: no remaining months",IF(AND(J16>0,Phasing!G16=0,I16<>0),"Budget not phased: remaining weights are 0",IF(OR(D16<Projects!$C$3,F16>EDATE(Projects!$C$3,35)),"Partly outside timeline",IF(Phasing!H16=0,"OK","Weights entered beyond duration (ignored)"))))))))
A17: 12 | F17: =IF(OR(D17="",E17=""),"",EDATE(D17,E17-1)) | H17: =IF(B17="","",'WIP Log'!C17) | I17: =IF(B17="","",N(G17)-N(H17)) | J17: =IF(OR(B17="",E17=""),"",MAX(0,E17-Phasing!F17+1)) | K17: =IF(B17="","",IF(AND(((YEAR(Projects!$C$2)-YEAR(Projects!$C$3))*12+MONTH(Projects!$C$2)-MONTH(Projects!$C$3)+1)+1>=1,((YEAR(Projects!$C$2)-YEAR(Projects!$C$3))*12+MONTH(Projects!$C$2)-MONTH(Projects!$C$3)+1)+1<=36),INDEX('Phased Budget'!$H17:$AQ17,((YEAR(Projects!$C$2)-YEAR(Projects!$C$3))*12+MONTH(Projects!$C$2)-MONTH(Projects!$C$3)+1)+1),0)) | L17: =IF(B17="","",SUMPRODUCT('Phased Budget'!$H17:$AQ17*(YEAR('Phased Budget'!$H$5:$AQ$5)=YEAR(Projects!$C$2)))) | M17: =IF(B17="","",SUMPRODUCT('WIP Log'!$D17:$AM17*('WIP Log'!$D$5:$AM$5<=Projects!$C$2)*(YEAR('WIP Log'!$D$5:$AM$5)=YEAR(Projects!$C$2)))+L17) | N17: =IF(B17="","",IF(OR(D17="",E17="",G17=""),"Missing start / duration / contract",IF(OR(E17<1,E17>24),"Duration must be 1–24",IF(I17<0,"WIP exceeds contract",IF(AND(J17=0,I17<>0),"Budget not phased: no remaining months",IF(AND(J17>0,Phasing!G17=0,I17<>0),"Budget not phased: remaining weights are 0",IF(OR(D17<Projects!$C$3,F17>EDATE(Projects!$C$3,35)),"Partly outside timeline",IF(Phasing!H17=0,"OK","Weights entered beyond duration (ignored)"))))))))
A18: 13 | F18: =IF(OR(D18="",E18=""),"",EDATE(D18,E18-1)) | H18: =IF(B18="","",'WIP Log'!C18) | I18: =IF(B18="","",N(G18)-N(H18)) | J18: =IF(OR(B18="",E18=""),"",MAX(0,E18-Phasing!F18+1)) | K18: =IF(B18="","",IF(AND(((YEAR(Projects!$C$2)-YEAR(Projects!$C$3))*12+MONTH(Projects!$C$2)-MONTH(Projects!$C$3)+1)+1>=1,((YEAR(Projects!$C$2)-YEAR(Projects!$C$3))*12+MONTH(Projects!$C$2)-MONTH(Projects!$C$3)+1)+1<=36),INDEX('Phased Budget'!$H18:$AQ18,((YEAR(Projects!$C$2)-YEAR(Projects!$C$3))*12+MONTH(Projects!$C$2)-MONTH(Projects!$C$3)+1)+1),0)) | L18: =IF(B18="","",SUMPRODUCT('Phased Budget'!$H18:$AQ18*(YEAR('Phased Budget'!$H$5:$AQ$5)=YEAR(Projects!$C$2)))) | M18: =IF(B18="","",SUMPRODUCT('WIP Log'!$D18:$AM18*('WIP Log'!$D$5:$AM$5<=Projects!$C$2)*(YEAR('WIP Log'!$D$5:$AM$5)=YEAR(Projects!$C$2)))+L18) | N18: =IF(B18="","",IF(OR(D18="",E18="",G18=""),"Missing start / duration / contract",IF(OR(E18<1,E18>24),"Duration must be 1–24",IF(I18<0,"WIP exceeds contract",IF(AND(J18=0,I18<>0),"Budget not phased: no remaining months",IF(AND(J18>0,Phasing!G18=0,I18<>0),"Budget not phased: remaining weights are 0",IF(OR(D18<Projects!$C$3,F18>EDATE(Projects!$C$3,35)),"Partly outside timeline",IF(Phasing!H18=0,"OK","Weights entered beyond duration (ignored)"))))))))
... A55: 50 | F55: =IF(OR(D55="",E55=""),"",EDATE(D55,E55-1)) | H55: =IF(B55="","",'WIP Log'!C55) | I55: =IF(B55="","",N(G55)-N(H55)) | J55: =IF(OR(B55="",E55=""),"",MAX(0,E55-Phasing!F55+1)) | K55: =IF(B55="","",IF(AND(((YEAR(Projects!$C$2)-YEAR(Projects!$C$3))*12+MONTH(Projects!$C$2)-MONTH(Projects!$C$3)+1)+1>=1,((YEAR(Projects!$C$2)-YEAR(Projects!$C$3))*12+MONTH(Projects!$C$2)-MONTH(Projects!$C$3)+1)+1<=36),INDEX('Phased Budget'!$H55:$AQ55,((YEAR(Projects!$C$2)-YEAR(Projects!$C$3))*12+MONTH(Projects!$C$2)-MONTH(Projects!$C$3)+1)+1),0)) | L55: =IF(B55="","",SUMPRODUCT('Phased Budget'!$H55:$AQ55*(YEAR('Phased Budget'!$H$5:$AQ$5)=YEAR(Projects!$C$2)))) | M55: =IF(B55="","",SUMPRODUCT('WIP Log'!$D55:$AM55*('WIP Log'!$D$5:$AM$5<=Projects!$C$2)*(YEAR('WIP Log'!$D$5:$AM$5)=YEAR(Projects!$C$2)))+L55) | N55: =IF(B55="","",IF(OR(D55="",E55="",G55=""),"Missing start / duration / contract",IF(OR(E55<1,E55>24),"Duration must be 1–24",IF(I55<0,"WIP exceeds contract",IF(AND(J55=0,I55<>0),"Budget not phased: no remaining months",IF(AND(J55>0,Phasing!G55=0,I55<>0),"Budget not phased: remaining weights are 0",IF(OR(D55<Projects!$C$3,F55>EDATE(Projects!$C$3,35)),"Partly outside timeline",IF(Phasing!H55=0,"OK","Weights entered beyond duration (ignored)"))))))))
B57: TOTAL | G57: =SUM(G6:G55) -> 10000 | H57: =SUM(H6:H55) -> 1000 | I57: =SUM(I6:I55) -> 9000 | K57: =SUM(K6:K55) -> 2250 | L57: =SUM(L6:L55) -> 4500 | M57: =SUM(M6:M55) -> 5500 | N57: =COUNTIFS(N6:N55,"<>OK",B6:B55,"<>")&" project(s) need attention" -> 0 project(s) need attention

Sheet Phasing
A1: Phasing Weights
H2: month index | I2: 1 | J2: 2 | K2: 3 | L2: 4 | M2: 5 | N2: 6 | O2: 7 | P2: 8 | Q2: 9 | R2: 10 | S2: 11 | T2: 12 | U2: 13 | V2: 14 | W2: 15 | X2: 16 | Y2: 17 | Z2: 18 | AA2: 19 | AB2: 20 | AC2: 21 | AD2: 22 | AE2: 23 | AF2: 24 | AH2: 1 | AI2: 2 | AJ2: 3 | AK2: 4 | AL2: 5 | AM2: 6 | AN2: 7 | AO2: 8 | AP2: 9 | AQ2: 10 | AR2: 11 | AS2: 12 | AT2: 13 | AU2: 14 | AV2: 15 | AW2: 16 | AX2: 17 | AY2: 18 | AZ2: 19 | BA2: 20 | BB2: 21 | BC2: 22 | BD2: 23 | BE2: 24
A3: Enter raw weights in the yellow cells (month 1 = Starting Month). They are renormalised to 1.0 automatically. Leave a row blank for equal weights.
I4: RAW WEIGHTS (input) → | AH4: NORMALISED WEIGHTS, FULL DURATION (Σ = 1.0) →
A5: # | B5: Project Name | C5: Duration | D5: Weights entered | E5: Σ weights (full duration) | F5: First remaining month # | G5: Σ weights (remaining months) | H5: Non-zero weights beyond duration | I5: M1 | J5: M2 | K5: M3 | L5: M4 | M5: M5 | N5: M6 | O5: M7 | P5: M8 | Q5: M9 | R5: M10 | S5: M11 | T5: M12 | U5: M13 | V5: M14 | W5: M15 | X5: M16 | Y5: M17 | Z5: M18 | AA5: M19 | AB5: M20 | AC5: M21 | AD5: M22 | AE5: M23 | AF5: M24 | AH5: M1 | AI5: M2 | AJ5: M3 | AK5: M4 | AL5: M5 | AM5: M6 | AN5: M7 | AO5: M8 | AP5: M9 | AQ5: M10 | AR5: M11 | AS5: M12 | AT5: M13 | AU5: M14 | AV5: M15 | AW5: M16 | AX5: M17 | AY5: M18 | AZ5: M19 | BA5: M20 | BB5: M21 | BC5: M22 | BD5: M23 | BE5: M24 | BF5: Check Σ
A6: 1 | B6: =IF(Projects!B6="","",Projects!B6) -> Example Project (slide) | C6: =IF(Projects!E6="","",Projects!E6) -> 5 | D6: =COUNT($I6:$AF6) -> 5 | E6: =IF(C6="",0,IF(D6=0,C6,SUMPRODUCT($I6:$AF6*($I$2:$AF$2<=C6)))) -> 9 | F6: =IF(OR(C6="",Projects!D6=""),1,MAX(1,((YEAR(Projects!$C$2)-YEAR(Projects!D6))*12+MONTH(Projects!$C$2)-MONTH(Projects!D6)+1)+1)) -> 2 | G6: =IF(C6="",0,IF(D6=0,MAX(0,C6-F6+1),SUMPRODUCT($I6:$AF6*($I$2:$AF$2>=F6)*($I$2:$AF$2<=C6)))) -> 8 | H6: =IF(C6="",0,SUMPRODUCT(($I6:$AF6<>0)*($I$2:$AF$2>C6))) -> 0 | I6: 1 | J6: 2 | K6: 2 | L6: 2 | M6: 2 | AH6: =IF(OR(C6="",AH$2>C6,E6=0),"",IF(D6=0,1/C6,N(I6)/E6)) -> 0.11111111 | AI6: =IF(OR(C6="",AI$2>C6,E6=0),"",IF(D6=0,1/C6,N(J6)/E6)) -> 0.22222222 | AJ6: =IF(OR(C6="",AJ$2>C6,E6=0),"",IF(D6=0,1/C6,N(K6)/E6)) -> 0.22222222 | AK6: =IF(OR(C6="",AK$2>C6,E6=0),"",IF(D6=0,1/C6,N(L6)/E6)) -> 0.22222222 | AL6: =IF(OR(C6="",AL$2>C6,E6=0),"",IF(D6=0,1/C6,N(M6)/E6)) -> 0.22222222 | AM6: =IF(OR(C6="",AM$2>C6,E6=0),"",IF(D6=0,1/C6,N(N6)/E6)) | AN6: =IF(OR(C6="",AN$2>C6,E6=0),"",IF(D6=0,1/C6,N(O6)/E6)) | AO6: =IF(OR(C6="",AO$2>C6,E6=0),"",IF(D6=0,1/C6,N(P6)/E6)) | AP6: =IF(OR(C6="",AP$2>C6,E6=0),"",IF(D6=0,1/C6,N(Q6)/E6)) | AQ6: =IF(OR(C6="",AQ$2>C6,E6=0),"",IF(D6=0,1/C6,N(R6)/E6)) | AR6: =IF(OR(C6="",AR$2>C6,E6=0),"",IF(D6=0,1/C6,N(S6)/E6)) | AS6: =IF(OR(C6="",AS$2>C6,E6=0),"",IF(D6=0,1/C6,N(T6)/E6)) | AT6: =IF(OR(C6="",AT$2>C6,E6=0),"",IF(D6=0,1/C6,N(U6)/E6)) | AU6: =IF(OR(C6="",AU$2>C6,E6=0),"",IF(D6=0,1/C6,N(V6)/E6)) | AV6: =IF(OR(C6="",AV$2>C6,E6=0),"",IF(D6=0,1/C6,N(W6)/E6)) | AW6: =IF(OR(C6="",AW$2>C6,E6=0),"",IF(D6=0,1/C6,N(X6)/E6)) | AX6: =IF(OR(C6="",AX$2>C6,E6=0),"",IF(D6=0,1/C6,N(Y6)/E6)) | AY6: =IF(OR(C6="",AY$2>C6,E6=0),"",IF(D6=0,1/C6,N(Z6)/E6)) | AZ6: =IF(OR(C6="",AZ$2>C6,E6=0),"",IF(D6=0,1/C6,N(AA6)/E6)) | BA6: =IF(OR(C6="",BA$2>C6,E6=0),"",IF(D6=0,1/C6,N(AB6)/E6)) | BB6: =IF(OR(C6="",BB$2>C6,E6=0),"",IF(D6=0,1/C6,N(AC6)/E6)) | BC6: =IF(OR(C6="",BC$2>C6,E6=0),"",IF(D6=0,1/C6,N(AD6)/E6)) | BD6: =IF(OR(C6="",BD$2>C6,E6=0),"",IF(D6=0,1/C6,N(AE6)/E6)) | BE6: =IF(OR(C6="",BE$2>C6,E6=0),"",IF(D6=0,1/C6,N(AF6)/E6)) | BF6: =IF(C6="","",SUM(AH6:BE6)) -> 1
A7: 2 | B7: =IF(Projects!B7="","",Projects!B7) | C7: =IF(Projects!E7="","",Projects!E7) | D7: =COUNT($I7:$AF7) -> 0 | E7: =IF(C7="",0,IF(D7=0,C7,SUMPRODUCT($I7:$AF7*($I$2:$AF$2<=C7)))) -> 0 | F7: =IF(OR(C7="",Projects!D7=""),1,MAX(1,((YEAR(Projects!$C$2)-YEAR(Projects!D7))*12+MONTH(Projects!$C$2)-MONTH(Projects!D7)+1)+1)) -> 1 | G7: =IF(C7="",0,IF(D7=0,MAX(0,C7-F7+1),SUMPRODUCT($I7:$AF7*($I$2:$AF$2>=F7)*($I$2:$AF$2<=C7)))) -> 0 | H7: =IF(C7="",0,SUMPRODUCT(($I7:$AF7<>0)*($I$2:$AF$2>C7))) -> 0 | AH7: =IF(OR(C7="",AH$2>C7,E7=0),"",IF(D7=0,1/C7,N(I7)/E7)) | AI7: =IF(OR(C7="",AI$2>C7,E7=0),"",IF(D7=0,1/C7,N(J7)/E7)) | AJ7: =IF(OR(C7="",AJ$2>C7,E7=0),"",IF(D7=0,1/C7,N(K7)/E7)) | AK7: =IF(OR(C7="",AK$2>C7,E7=0),"",IF(D7=0,1/C7,N(L7)/E7)) | AL7: =IF(OR(C7="",AL$2>C7,E7=0),"",IF(D7=0,1/C7,N(M7)/E7)) | AM7: =IF(OR(C7="",AM$2>C7,E7=0),"",IF(D7=0,1/C7,N(N7)/E7)) | AN7: =IF(OR(C7="",AN$2>C7,E7=0),"",IF(D7=0,1/C7,N(O7)/E7)) | AO7: =IF(OR(C7="",AO$2>C7,E7=0),"",IF(D7=0,1/C7,N(P7)/E7)) | AP7: =IF(OR(C7="",AP$2>C7,E7=0),"",IF(D7=0,1/C7,N(Q7)/E7)) | AQ7: =IF(OR(C7="",AQ$2>C7,E7=0),"",IF(D7=0,1/C7,N(R7)/E7)) | AR7: =IF(OR(C7="",AR$2>C7,E7=0),"",IF(D7=0,1/C7,N(S7)/E7)) | AS7: =IF(OR(C7="",AS$2>C7,E7=0),"",IF(D7=0,1/C7,N(T7)/E7)) | AT7: =IF(OR(C7="",AT$2>C7,E7=0),"",IF(D7=0,1/C7,N(U7)/E7)) | AU7: =IF(OR(C7="",AU$2>C7,E7=0),"",IF(D7=0,1/C7,N(V7)/E7)) | AV7: =IF(OR(C7="",AV$2>C7,E7=0),"",IF(D7=0,1/C7,N(W7)/E7)) | AW7: =IF(OR(C7="",AW$2>C7,E7=0),"",IF(D7=0,1/C7,N(X7)/E7)) | AX7: =IF(OR(C7="",AX$2>C7,E7=0),"",IF(D7=0,1/C7,N(Y7)/E7)) | AY7: =IF(OR(C7="",AY$2>C7,E7=0),"",IF(D7=0,1/C7,N(Z7)/E7)) | AZ7: =IF(OR(C7="",AZ$2>C7,E7=0),"",IF(D7=0,1/C7,N(AA7)/E7)) | BA7: =IF(OR(C7="",BA$2>C7,E7=0),"",IF(D7=0,1/C7,N(AB7)/E7)) | BB7: =IF(OR(C7="",BB$2>C7,E7=0),"",IF(D7=0,1/C7,N(AC7)/E7)) | BC7: =IF(OR(C7="",BC$2>C7,E7=0),"",IF(D7=0,1/C7,N(AD7)/E7)) | BD7: =IF(OR(C7="",BD$2>C7,E7=0),"",IF(D7=0,1/C7,N(AE7)/E7)) | BE7: =IF(OR(C7="",BE$2>C7,E7=0),"",IF(D7=0,1/C7,N(AF7)/E7)) | BF7: =IF(C7="","",SUM(AH7:BE7))
A8: 3 | B8: =IF(Projects!B8="","",Projects!B8) | C8: =IF(Projects!E8="","",Projects!E8) | D8: =COUNT($I8:$AF8) -> 0 | E8: =IF(C8="",0,IF(D8=0,C8,SUMPRODUCT($I8:$AF8*($I$2:$AF$2<=C8)))) -> 0 | F8: =IF(OR(C8="",Projects!D8=""),1,MAX(1,((YEAR(Projects!$C$2)-YEAR(Projects!D8))*12+MONTH(Projects!$C$2)-MONTH(Projects!D8)+1)+1)) -> 1 | G8: =IF(C8="",0,IF(D8=0,MAX(0,C8-F8+1),SUMPRODUCT($I8:$AF8*($I$2:$AF$2>=F8)*($I$2:$AF$2<=C8)))) -> 0 | H8: =IF(C8="",0,SUMPRODUCT(($I8:$AF8<>0)*($I$2:$AF$2>C8))) -> 0 | AH8: =IF(OR(C8="",AH$2>C8,E8=0),"",IF(D8=0,1/C8,N(I8)/E8)) | AI8: =IF(OR(C8="",AI$2>C8,E8=0),"",IF(D8=0,1/C8,N(J8)/E8)) | AJ8: =IF(OR(C8="",AJ$2>C8,E8=0),"",IF(D8=0,1/C8,N(K8)/E8)) | AK8: =IF(OR(C8="",AK$2>C8,E8=0),"",IF(D8=0,1/C8,N(L8)/E8)) | AL8: =IF(OR(C8="",AL$2>C8,E8=0),"",IF(D8=0,1/C8,N(M8)/E8)) | AM8: =IF(OR(C8="",AM$2>C8,E8=0),"",IF(D8=0,1/C8,N(N8)/E8)) | AN8: =IF(OR(C8="",AN$2>C8,E8=0),"",IF(D8=0,1/C8,N(O8)/E8)) | AO8: =IF(OR(C8="",AO$2>C8,E8=0),"",IF(D8=0,1/C8,N(P8)/E8)) | AP8: =IF(OR(C8="",AP$2>C8,E8=0),"",IF(D8=0,1/C8,N(Q8)/E8)) | AQ8: =IF(OR(C8="",AQ$2>C8,E8=0),"",IF(D8=0,1/C8,N(R8)/E8)) | AR8: =IF(OR(C8="",AR$2>C8,E8=0),"",IF(D8=0,1/C8,N(S8)/E8)) | AS8: =IF(OR(C8="",AS$2>C8,E8=0),"",IF(D8=0,1/C8,N(T8)/E8)) | AT8: =IF(OR(C8="",AT$2>C8,E8=0),"",IF(D8=0,1/C8,N(U8)/E8)) | AU8: =IF(OR(C8="",AU$2>C8,E8=0),"",IF(D8=0,1/C8,N(V8)/E8)) | AV8: =IF(OR(C8="",AV$2>C8,E8=0),"",IF(D8=0,1/C8,N(W8)/E8)) | AW8: =IF(OR(C8="",AW$2>C8,E8=0),"",IF(D8=0,1/C8,N(X8)/E8)) | AX8: =IF(OR(C8="",AX$2>C8,E8=0),"",IF(D8=0,1/C8,N(Y8)/E8)) | AY8: =IF(OR(C8="",AY$2>C8,E8=0),"",IF(D8=0,1/C8,N(Z8)/E8)) | AZ8: =IF(OR(C8="",AZ$2>C8,E8=0),"",IF(D8=0,1/C8,N(AA8)/E8)) | BA8: =IF(OR(C8="",BA$2>C8,E8=0),"",IF(D8=0,1/C8,N(AB8)/E8)) | BB8: =IF(OR(C8="",BB$2>C8,E8=0),"",IF(D8=0,1/C8,N(AC8)/E8)) | BC8: =IF(OR(C8="",BC$2>C8,E8=0),"",IF(D8=0,1/C8,N(AD8)/E8)) | BD8: =IF(OR(C8="",BD$2>C8,E8=0),"",IF(D8=0,1/C8,N(AE8)/E8)) | BE8: =IF(OR(C8="",BE$2>C8,E8=0),"",IF(D8=0,1/C8,N(AF8)/E8)) | BF8: =IF(C8="","",SUM(AH8:BE8))
A9: 4 | B9: =IF(Projects!B9="","",Projects!B9) | C9: =IF(Projects!E9="","",Projects!E9) | D9: =COUNT($I9:$AF9) -> 0 | E9: =IF(C9="",0,IF(D9=0,C9,SUMPRODUCT($I9:$AF9*($I$2:$AF$2<=C9)))) -> 0 | F9: =IF(OR(C9="",Projects!D9=""),1,MAX(1,((YEAR(Projects!$C$2)-YEAR(Projects!D9))*12+MONTH(Projects!$C$2)-MONTH(Projects!D9)+1)+1)) -> 1 | G9: =IF(C9="",0,IF(D9=0,MAX(0,C9-F9+1),SUMPRODUCT($I9:$AF9*($I$2:$AF$2>=F9)*($I$2:$AF$2<=C9)))) -> 0 | H9: =IF(C9="",0,SUMPRODUCT(($I9:$AF9<>0)*($I$2:$AF$2>C9))) -> 0 | AH9: =IF(OR(C9="",AH$2>C9,E9=0),"",IF(D9=0,1/C9,N(I9)/E9)) | AI9: =IF(OR(C9="",AI$2>C9,E9=0),"",IF(D9=0,1/C9,N(J9)/E9)) | AJ9: =IF(OR(C9="",AJ$2>C9,E9=0),"",IF(D9=0,1/C9,N(K9)/E9)) | AK9: =IF(OR(C9="",AK$2>C9,E9=0),"",IF(D9=0,1/C9,N(L9)/E9)) | AL9: =IF(OR(C9="",AL$2>C9,E9=0),"",IF(D9=0,1/C9,N(M9)/E9)) | AM9: =IF(OR(C9="",AM$2>C9,E9=0),"",IF(D9=0,1/C9,N(N9)/E9)) | AN9: =IF(OR(C9="",AN$2>C9,E9=0),"",IF(D9=0,1/C9,N(O9)/E9)) | AO9: =IF(OR(C9="",AO$2>C9,E9=0),"",IF(D9=0,1/C9,N(P9)/E9)) | AP9: =IF(OR(C9="",AP$2>C9,E9=0),"",IF(D9=0,1/C9,N(Q9)/E9)) | AQ9: =IF(OR(C9="",AQ$2>C9,E9=0),"",IF(D9=0,1/C9,N(R9)/E9)) | AR9: =IF(OR(C9="",AR$2>C9,E9=0),"",IF(D9=0,1/C9,N(S9)/E9)) | AS9: =IF(OR(C9="",AS$2>C9,E9=0),"",IF(D9=0,1/C9,N(T9)/E9)) | AT9: =IF(OR(C9="",AT$2>C9,E9=0),"",IF(D9=0,1/C9,N(U9)/E9)) | AU9: =IF(OR(C9="",AU$2>C9,E9=0),"",IF(D9=0,1/C9,N(V9)/E9)) | AV9: =IF(OR(C9="",AV$2>C9,E9=0),"",IF(D9=0,1/C9,N(W9)/E9)) | AW9: =IF(OR(C9="",AW$2>C9,E9=0),"",IF(D9=0,1/C9,N(X9)/E9)) | AX9: =IF(OR(C9="",AX$2>C9,E9=0),"",IF(D9=0,1/C9,N(Y9)/E9)) | AY9: =IF(OR(C9="",AY$2>C9,E9=0),"",IF(D9=0,1/C9,N(Z9)/E9)) | AZ9: =IF(OR(C9="",AZ$2>C9,E9=0),"",IF(D9=0,1/C9,N(AA9)/E9)) | BA9: =IF(OR(C9="",BA$2>C9,E9=0),"",IF(D9=0,1/C9,N(AB9)/E9)) | BB9: =IF(OR(C9="",BB$2>C9,E9=0),"",IF(D9=0,1/C9,N(AC9)/E9)) | BC9: =IF(OR(C9="",BC$2>C9,E9=0),"",IF(D9=0,1/C9,N(AD9)/E9)) | BD9: =IF(OR(C9="",BD$2>C9,E9=0),"",IF(D9=0,1/C9,N(AE9)/E9)) | BE9: =IF(OR(C9="",BE$2>C9,E9=0),"",IF(D9=0,1/C9,N(AF9)/E9)) | BF9: =IF(C9="","",SUM(AH9:BE9))
A10: 5 | B10: =IF(Projects!B10="","",Projects!B10) | C10: =IF(Projects!E10="","",Projects!E10) | D10: =COUNT($I10:$AF10) -> 0 | E10: =IF(C10="",0,IF(D10=0,C10,SUMPRODUCT($I10:$AF10*($I$2:$AF$2<=C10)))) -> 0 | F10: =IF(OR(C10="",Projects!D10=""),1,MAX(1,((YEAR(Projects!$C$2)-YEAR(Projects!D10))*12+MONTH(Projects!$C$2)-MONTH(Projects!D10)+1)+1)) -> 1 | G10: =IF(C10="",0,IF(D10=0,MAX(0,C10-F10+1),SUMPRODUCT($I10:$AF10*($I$2:$AF$2>=F10)*($I$2:$AF$2<=C10)))) -> 0 | H10: =IF(C10="",0,SUMPRODUCT(($I10:$AF10<>0)*($I$2:$AF$2>C10))) -> 0 | AH10: =IF(OR(C10="",AH$2>C10,E10=0),"",IF(D10=0,1/C10,N(I10)/E10)) | AI10: =IF(OR(C10="",AI$2>C10,E10=0),"",IF(D10=0,1/C10,N(J10)/E10)) | AJ10: =IF(OR(C10="",AJ$2>C10,E10=0),"",IF(D10=0,1/C10,N(K10)/E10)) | AK10: =IF(OR(C10="",AK$2>C10,E10=0),"",IF(D10=0,1/C10,N(L10)/E10)) | AL10: =IF(OR(C10="",AL$2>C10,E10=0),"",IF(D10=0,1/C10,N(M10)/E10)) | AM10: =IF(OR(C10="",AM$2>C10,E10=0),"",IF(D10=0,1/C10,N(N10)/E10)) | AN10: =IF(OR(C10="",AN$2>C10,E10=0),"",IF(D10=0,1/C10,N(O10)/E10)) | AO10: =IF(OR(C10="",AO$2>C10,E10=0),"",IF(D10=0,1/C10,N(P10)/E10)) | AP10: =IF(OR(C10="",AP$2>C10,E10=0),"",IF(D10=0,1/C10,N(Q10)/E10)) | AQ10: =IF(OR(C10="",AQ$2>C10,E10=0),"",IF(D10=0,1/C10,N(R10)/E10)) | AR10: =IF(OR(C10="",AR$2>C10,E10=0),"",IF(D10=0,1/C10,N(S10)/E10)) | AS10: =IF(OR(C10="",AS$2>C10,E10=0),"",IF(D10=0,1/C10,N(T10)/E10)) | AT10: =IF(OR(C10="",AT$2>C10,E10=0),"",IF(D10=0,1/C10,N(U10)/E10)) | AU10: =IF(OR(C10="",AU$2>C10,E10=0),"",IF(D10=0,1/C10,N(V10)/E10)) | AV10: =IF(OR(C10="",AV$2>C10,E10=0),"",IF(D10=0,1/C10,N(W10)/E10)) | AW10: =IF(OR(C10="",AW$2>C10,E10=0),"",IF(D10=0,1/C10,N(X10)/E10)) | AX10: =IF(OR(C10="",AX$2>C10,E10=0),"",IF(D10=0,1/C10,N(Y10)/E10)) | AY10: =IF(OR(C10="",AY$2>C10,E10=0),"",IF(D10=0,1/C10,N(Z10)/E10)) | AZ10: =IF(OR(C10="",AZ$2>C10,E10=0),"",IF(D10=0,1/C10,N(AA10)/E10)) | BA10: =IF(OR(C10="",BA$2>C10,E10=0),"",IF(D10=0,1/C10,N(AB10)/E10)) | BB10: =IF(OR(C10="",BB$2>C10,E10=0),"",IF(D10=0,1/C10,N(AC10)/E10)) | BC10: =IF(OR(C10="",BC$2>C10,E10=0),"",IF(D10=0,1/C10,N(AD10)/E10)) | BD10: =IF(OR(C10="",BD$2>C10,E10=0),"",IF(D10=0,1/C10,N(AE10)/E10)) | BE10: =IF(OR(C10="",BE$2>C10,E10=0),"",IF(D10=0,1/C10,N(AF10)/E10)) | BF10: =IF(C10="","",SUM(AH10:BE10))
A11: 6 | B11: =IF(Projects!B11="","",Projects!B11) | C11: =IF(Projects!E11="","",Projects!E11) | D11: =COUNT($I11:$AF11) -> 0 | E11: =IF(C11="",0,IF(D11=0,C11,SUMPRODUCT($I11:$AF11*($I$2:$AF$2<=C11)))) -> 0 | F11: =IF(OR(C11="",Projects!D11=""),1,MAX(1,((YEAR(Projects!$C$2)-YEAR(Projects!D11))*12+MONTH(Projects!$C$2)-MONTH(Projects!D11)+1)+1)) -> 1 | G11: =IF(C11="",0,IF(D11=0,MAX(0,C11-F11+1),SUMPRODUCT($I11:$AF11*($I$2:$AF$2>=F11)*($I$2:$AF$2<=C11)))) -> 0 | H11: =IF(C11="",0,SUMPRODUCT(($I11:$AF11<>0)*($I$2:$AF$2>C11))) -> 0 | AH11: =IF(OR(C11="",AH$2>C11,E11=0),"",IF(D11=0,1/C11,N(I11)/E11)) | AI11: =IF(OR(C11="",AI$2>C11,E11=0),"",IF(D11=0,1/C11,N(J11)/E11)) | AJ11: =IF(OR(C11="",AJ$2>C11,E11=0),"",IF(D11=0,1/C11,N(K11)/E11)) | AK11: =IF(OR(C11="",AK$2>C11,E11=0),"",IF(D11=0,1/C11,N(L11)/E11)) | AL11: =IF(OR(C11="",AL$2>C11,E11=0),"",IF(D11=0,1/C11,N(M11)/E11)) | AM11: =IF(OR(C11="",AM$2>C11,E11=0),"",IF(D11=0,1/C11,N(N11)/E11)) | AN11: =IF(OR(C11="",AN$2>C11,E11=0),"",IF(D11=0,1/C11,N(O11)/E11)) | AO11: =IF(OR(C11="",AO$2>C11,E11=0),"",IF(D11=0,1/C11,N(P11)/E11)) | AP11: =IF(OR(C11="",AP$2>C11,E11=0),"",IF(D11=0,1/C11,N(Q11)/E11)) | AQ11: =IF(OR(C11="",AQ$2>C11,E11=0),"",IF(D11=0,1/C11,N(R11)/E11)) | AR11: =IF(OR(C11="",AR$2>C11,E11=0),"",IF(D11=0,1/C11,N(S11)/E11)) | AS11: =IF(OR(C11="",AS$2>C11,E11=0),"",IF(D11=0,1/C11,N(T11)/E11)) | AT11: =IF(OR(C11="",AT$2>C11,E11=0),"",IF(D11=0,1/C11,N(U11)/E11)) | AU11: =IF(OR(C11="",AU$2>C11,E11=0),"",IF(D11=0,1/C11,N(V11)/E11)) | AV11: =IF(OR(C11="",AV$2>C11,E11=0),"",IF(D11=0,1/C11,N(W11)/E11)) | AW11: =IF(OR(C11="",AW$2>C11,E11=0),"",IF(D11=0,1/C11,N(X11)/E11)) | AX11: =IF(OR(C11="",AX$2>C11,E11=0),"",IF(D11=0,1/C11,N(Y11)/E11)) | AY11: =IF(OR(C11="",AY$2>C11,E11=0),"",IF(D11=0,1/C11,N(Z11)/E11)) | AZ11: =IF(OR(C11="",AZ$2>C11,E11=0),"",IF(D11=0,1/C11,N(AA11)/E11)) | BA11: =IF(OR(C11="",BA$2>C11,E11=0),"",IF(D11=0,1/C11,N(AB11)/E11)) | BB11: =IF(OR(C11="",BB$2>C11,E11=0),"",IF(D11=0,1/C11,N(AC11)/E11)) | BC11: =IF(OR(C11="",BC$2>C11,E11=0),"",IF(D11=0,1/C11,N(AD11)/E11)) | BD11: =IF(OR(C11="",BD$2>C11,E11=0),"",IF(D11=0,1/C11,N(AE11)/E11)) | BE11: =IF(OR(C11="",BE$2>C11,E11=0),"",IF(D11=0,1/C11,N(AF11)/E11)) | BF11: =IF(C11="","",SUM(AH11:BE11))
A12: 7 | B12: =IF(Projects!B12="","",Projects!B12) | C12: =IF(Projects!E12="","",Projects!E12) | D12: =COUNT($I12:$AF12) -> 0 | E12: =IF(C12="",0,IF(D12=0,C12,SUMPRODUCT($I12:$AF12*($I$2:$AF$2<=C12)))) -> 0 | F12: =IF(OR(C12="",Projects!D12=""),1,MAX(1,((YEAR(Projects!$C$2)-YEAR(Projects!D12))*12+MONTH(Projects!$C$2)-MONTH(Projects!D12)+1)+1)) -> 1 | G12: =IF(C12="",0,IF(D12=0,MAX(0,C12-F12+1),SUMPRODUCT($I12:$AF12*($I$2:$AF$2>=F12)*($I$2:$AF$2<=C12)))) -> 0 | H12: =IF(C12="",0,SUMPRODUCT(($I12:$AF12<>0)*($I$2:$AF$2>C12))) -> 0 | AH12: =IF(OR(C12="",AH$2>C12,E12=0),"",IF(D12=0,1/C12,N(I12)/E12)) | AI12: =IF(OR(C12="",AI$2>C12,E12=0),"",IF(D12=0,1/C12,N(J12)/E12)) | AJ12: =IF(OR(C12="",AJ$2>C12,E12=0),"",IF(D12=0,1/C12,N(K12)/E12)) | AK12: =IF(OR(C12="",AK$2>C12,E12=0),"",IF(D12=0,1/C12,N(L12)/E12)) | AL12: =IF(OR(C12="",AL$2>C12,E12=0),"",IF(D12=0,1/C12,N(M12)/E12)) | AM12: =IF(OR(C12="",AM$2>C12,E12=0),"",IF(D12=0,1/C12,N(N12)/E12)) | AN12: =IF(OR(C12="",AN$2>C12,E12=0),"",IF(D12=0,1/C12,N(O12)/E12)) | AO12: =IF(OR(C12="",AO$2>C12,E12=0),"",IF(D12=0,1/C12,N(P12)/E12)) | AP12: =IF(OR(C12="",AP$2>C12,E12=0),"",IF(D12=0,1/C12,N(Q12)/E12)) | AQ12: =IF(OR(C12="",AQ$2>C12,E12=0),"",IF(D12=0,1/C12,N(R12)/E12)) | AR12: =IF(OR(C12="",AR$2>C12,E12=0),"",IF(D12=0,1/C12,N(S12)/E12)) | AS12: =IF(OR(C12="",AS$2>C12,E12=0),"",IF(D12=0,1/C12,N(T12)/E12)) | AT12: =IF(OR(C12="",AT$2>C12,E12=0),"",IF(D12=0,1/C12,N(U12)/E12)) | AU12: =IF(OR(C12="",AU$2>C12,E12=0),"",IF(D12=0,1/C12,N(V12)/E12)) | AV12: =IF(OR(C12="",AV$2>C12,E12=0),"",IF(D12=0,1/C12,N(W12)/E12)) | AW12: =IF(OR(C12="",AW$2>C12,E12=0),"",IF(D12=0,1/C12,N(X12)/E12)) | AX12: =IF(OR(C12="",AX$2>C12,E12=0),"",IF(D12=0,1/C12,N(Y12)/E12)) | AY12: =IF(OR(C12="",AY$2>C12,E12=0),"",IF(D12=0,1/C12,N(Z12)/E12)) | AZ12: =IF(OR(C12="",AZ$2>C12,E12=0),"",IF(D12=0,1/C12,N(AA12)/E12)) | BA12: =IF(OR(C12="",BA$2>C12,E12=0),"",IF(D12=0,1/C12,N(AB12)/E12)) | BB12: =IF(OR(C12="",BB$2>C12,E12=0),"",IF(D12=0,1/C12,N(AC12)/E12)) | BC12: =IF(OR(C12="",BC$2>C12,E12=0),"",IF(D12=0,1/C12,N(AD12)/E12)) | BD12: =IF(OR(C12="",BD$2>C12,E12=0),"",IF(D12=0,1/C12,N(AE12)/E12)) | BE12: =IF(OR(C12="",BE$2>C12,E12=0),"",IF(D12=0,1/C12,N(AF12)/E12)) | BF12: =IF(C12="","",SUM(AH12:BE12))
A13: 8 | B13: =IF(Projects!B13="","",Projects!B13) | C13: =IF(Projects!E13="","",Projects!E13) | D13: =COUNT($I13:$AF13) -> 0 | E13: =IF(C13="",0,IF(D13=0,C13,SUMPRODUCT($I13:$AF13*($I$2:$AF$2<=C13)))) -> 0 | F13: =IF(OR(C13="",Projects!D13=""),1,MAX(1,((YEAR(Projects!$C$2)-YEAR(Projects!D13))*12+MONTH(Projects!$C$2)-MONTH(Projects!D13)+1)+1)) -> 1 | G13: =IF(C13="",0,IF(D13=0,MAX(0,C13-F13+1),SUMPRODUCT($I13:$AF13*($I$2:$AF$2>=F13)*($I$2:$AF$2<=C13)))) -> 0 | H13: =IF(C13="",0,SUMPRODUCT(($I13:$AF13<>0)*($I$2:$AF$2>C13))) -> 0 | AH13: =IF(OR(C13="",AH$2>C13,E13=0),"",IF(D13=0,1/C13,N(I13)/E13)) | AI13: =IF(OR(C13="",AI$2>C13,E13=0),"",IF(D13=0,1/C13,N(J13)/E13)) | AJ13: =IF(OR(C13="",AJ$2>C13,E13=0),"",IF(D13=0,1/C13,N(K13)/E13)) | AK13: =IF(OR(C13="",AK$2>C13,E13=0),"",IF(D13=0,1/C13,N(L13)/E13)) | AL13: =IF(OR(C13="",AL$2>C13,E13=0),"",IF(D13=0,1/C13,N(M13)/E13)) | AM13: =IF(OR(C13="",AM$2>C13,E13=0),"",IF(D13=0,1/C13,N(N13)/E13)) | AN13: =IF(OR(C13="",AN$2>C13,E13=0),"",IF(D13=0,1/C13,N(O13)/E13)) | AO13: =IF(OR(C13="",AO$2>C13,E13=0),"",IF(D13=0,1/C13,N(P13)/E13)) | AP13: =IF(OR(C13="",AP$2>C13,E13=0),"",IF(D13=0,1/C13,N(Q13)/E13)) | AQ13: =IF(OR(C13="",AQ$2>C13,E13=0),"",IF(D13=0,1/C13,N(R13)/E13)) | AR13: =IF(OR(C13="",AR$2>C13,E13=0),"",IF(D13=0,1/C13,N(S13)/E13)) | AS13: =IF(OR(C13="",AS$2>C13,E13=0),"",IF(D13=0,1/C13,N(T13)/E13)) | AT13: =IF(OR(C13="",AT$2>C13,E13=0),"",IF(D13=0,1/C13,N(U13)/E13)) | AU13: =IF(OR(C13="",AU$2>C13,E13=0),"",IF(D13=0,1/C13,N(V13)/E13)) | AV13: =IF(OR(C13="",AV$2>C13,E13=0),"",IF(D13=0,1/C13,N(W13)/E13)) | AW13: =IF(OR(C13="",AW$2>C13,E13=0),"",IF(D13=0,1/C13,N(X13)/E13)) | AX13: =IF(OR(C13="",AX$2>C13,E13=0),"",IF(D13=0,1/C13,N(Y13)/E13)) | AY13: =IF(OR(C13="",AY$2>C13,E13=0),"",IF(D13=0,1/C13,N(Z13)/E13)) | AZ13: =IF(OR(C13="",AZ$2>C13,E13=0),"",IF(D13=0,1/C13,N(AA13)/E13)) | BA13: =IF(OR(C13="",BA$2>C13,E13=0),"",IF(D13=0,1/C13,N(AB13)/E13)) | BB13: =IF(OR(C13="",BB$2>C13,E13=0),"",IF(D13=0,1/C13,N(AC13)/E13)) | BC13: =IF(OR(C13="",BC$2>C13,E13=0),"",IF(D13=0,1/C13,N(AD13)/E13)) | BD13: =IF(OR(C13="",BD$2>C13,E13=0),"",IF(D13=0,1/C13,N(AE13)/E13)) | BE13: =IF(OR(C13="",BE$2>C13,E13=0),"",IF(D13=0,1/C13,N(AF13)/E13)) | BF13: =IF(C13="","",SUM(AH13:BE13))
A14: 9 | B14: =IF(Projects!B14="","",Projects!B14) | C14: =IF(Projects!E14="","",Projects!E14) | D14: =COUNT($I14:$AF14) -> 0 | E14: =IF(C14="",0,IF(D14=0,C14,SUMPRODUCT($I14:$AF14*($I$2:$AF$2<=C14)))) -> 0 | F14: =IF(OR(C14="",Projects!D14=""),1,MAX(1,((YEAR(Projects!$C$2)-YEAR(Projects!D14))*12+MONTH(Projects!$C$2)-MONTH(Projects!D14)+1)+1)) -> 1 | G14: =IF(C14="",0,IF(D14=0,MAX(0,C14-F14+1),SUMPRODUCT($I14:$AF14*($I$2:$AF$2>=F14)*($I$2:$AF$2<=C14)))) -> 0 | H14: =IF(C14="",0,SUMPRODUCT(($I14:$AF14<>0)*($I$2:$AF$2>C14))) -> 0 | AH14: =IF(OR(C14="",AH$2>C14,E14=0),"",IF(D14=0,1/C14,N(I14)/E14)) | AI14: =IF(OR(C14="",AI$2>C14,E14=0),"",IF(D14=0,1/C14,N(J14)/E14)) | AJ14: =IF(OR(C14="",AJ$2>C14,E14=0),"",IF(D14=0,1/C14,N(K14)/E14)) | AK14: =IF(OR(C14="",AK$2>C14,E14=0),"",IF(D14=0,1/C14,N(L14)/E14)) | AL14: =IF(OR(C14="",AL$2>C14,E14=0),"",IF(D14=0,1/C14,N(M14)/E14)) | AM14: =IF(OR(C14="",AM$2>C14,E14=0),"",IF(D14=0,1/C14,N(N14)/E14)) | AN14: =IF(OR(C14="",AN$2>C14,E14=0),"",IF(D14=0,1/C14,N(O14)/E14)) | AO14: =IF(OR(C14="",AO$2>C14,E14=0),"",IF(D14=0,1/C14,N(P14)/E14)) | AP14: =IF(OR(C14="",AP$2>C14,E14=0),"",IF(D14=0,1/C14,N(Q14)/E14)) | AQ14: =IF(OR(C14="",AQ$2>C14,E14=0),"",IF(D14=0,1/C14,N(R14)/E14)) | AR14: =IF(OR(C14="",AR$2>C14,E14=0),"",IF(D14=0,1/C14,N(S14)/E14)) | AS14: =IF(OR(C14="",AS$2>C14,E14=0),"",IF(D14=0,1/C14,N(T14)/E14)) | AT14: =IF(OR(C14="",AT$2>C14,E14=0),"",IF(D14=0,1/C14,N(U14)/E14)) | AU14: =IF(OR(C14="",AU$2>C14,E14=0),"",IF(D14=0,1/C14,N(V14)/E14)) | AV14: =IF(OR(C14="",AV$2>C14,E14=0),"",IF(D14=0,1/C14,N(W14)/E14)) | AW14: =IF(OR(C14="",AW$2>C14,E14=0),"",IF(D14=0,1/C14,N(X14)/E14)) | AX14: =IF(OR(C14="",AX$2>C14,E14=0),"",IF(D14=0,1/C14,N(Y14)/E14)) | AY14: =IF(OR(C14="",AY$2>C14,E14=0),"",IF(D14=0,1/C14,N(Z14)/E14)) | AZ14: =IF(OR(C14="",AZ$2>C14,E14=0),"",IF(D14=0,1/C14,N(AA14)/E14)) | BA14: =IF(OR(C14="",BA$2>C14,E14=0),"",IF(D14=0,1/C14,N(AB14)/E14)) | BB14: =IF(OR(C14="",BB$2>C14,E14=0),"",IF(D14=0,1/C14,N(AC14)/E14)) | BC14: =IF(OR(C14="",BC$2>C14,E14=0),"",IF(D14=0,1/C14,N(AD14)/E14)) | BD14: =IF(OR(C14="",BD$2>C14,E14=0),"",IF(D14=0,1/C14,N(AE14)/E14)) | BE14: =IF(OR(C14="",BE$2>C14,E14=0),"",IF(D14=0,1/C14,N(AF14)/E14)) | BF14: =IF(C14="","",SUM(AH14:BE14))
A15: 10 | B15: =IF(Projects!B15="","",Projects!B15) | C15: =IF(Projects!E15="","",Projects!E15) | D15: =COUNT($I15:$AF15) -> 0 | E15: =IF(C15="",0,IF(D15=0,C15,SUMPRODUCT($I15:$AF15*($I$2:$AF$2<=C15)))) -> 0 | F15: =IF(OR(C15="",Projects!D15=""),1,MAX(1,((YEAR(Projects!$C$2)-YEAR(Projects!D15))*12+MONTH(Projects!$C$2)-MONTH(Projects!D15)+1)+1)) -> 1 | G15: =IF(C15="",0,IF(D15=0,MAX(0,C15-F15+1),SUMPRODUCT($I15:$AF15*($I$2:$AF$2>=F15)*($I$2:$AF$2<=C15)))) -> 0 | H15: =IF(C15="",0,SUMPRODUCT(($I15:$AF15<>0)*($I$2:$AF$2>C15))) -> 0 | AH15: =IF(OR(C15="",AH$2>C15,E15=0),"",IF(D15=0,1/C15,N(I15)/E15)) | AI15: =IF(OR(C15="",AI$2>C15,E15=0),"",IF(D15=0,1/C15,N(J15)/E15)) | AJ15: =IF(OR(C15="",AJ$2>C15,E15=0),"",IF(D15=0,1/C15,N(K15)/E15)) | AK15: =IF(OR(C15="",AK$2>C15,E15=0),"",IF(D15=0,1/C15,N(L15)/E15)) | AL15: =IF(OR(C15="",AL$2>C15,E15=0),"",IF(D15=0,1/C15,N(M15)/E15)) | AM15: =IF(OR(C15="",AM$2>C15,E15=0),"",IF(D15=0,1/C15,N(N15)/E15)) | AN15: =IF(OR(C15="",AN$2>C15,E15=0),"",IF(D15=0,1/C15,N(O15)/E15)) | AO15: =IF(OR(C15="",AO$2>C15,E15=0),"",IF(D15=0,1/C15,N(P15)/E15)) | AP15: =IF(OR(C15="",AP$2>C15,E15=0),"",IF(D15=0,1/C15,N(Q15)/E15)) | AQ15: =IF(OR(C15="",AQ$2>C15,E15=0),"",IF(D15=0,1/C15,N(R15)/E15)) | AR15: =IF(OR(C15="",AR$2>C15,E15=0),"",IF(D15=0,1/C15,N(S15)/E15)) | AS15: =IF(OR(C15="",AS$2>C15,E15=0),"",IF(D15=0,1/C15,N(T15)/E15)) | AT15: =IF(OR(C15="",AT$2>C15,E15=0),"",IF(D15=0,1/C15,N(U15)/E15)) | AU15: =IF(OR(C15="",AU$2>C15,E15=0),"",IF(D15=0,1/C15,N(V15)/E15)) | AV15: =IF(OR(C15="",AV$2>C15,E15=0),"",IF(D15=0,1/C15,N(W15)/E15)) | AW15: =IF(OR(C15="",AW$2>C15,E15=0),"",IF(D15=0,1/C15,N(X15)/E15)) | AX15: =IF(OR(C15="",AX$2>C15,E15=0),"",IF(D15=0,1/C15,N(Y15)/E15)) | AY15: =IF(OR(C15="",AY$2>C15,E15=0),"",IF(D15=0,1/C15,N(Z15)/E15)) | AZ15: =IF(OR(C15="",AZ$2>C15,E15=0),"",IF(D15=0,1/C15,N(AA15)/E15)) | BA15: =IF(OR(C15="",BA$2>C15,E15=0),"",IF(D15=0,1/C15,N(AB15)/E15)) | BB15: =IF(OR(C15="",BB$2>C15,E15=0),"",IF(D15=0,1/C15,N(AC15)/E15)) | BC15: =IF(OR(C15="",BC$2>C15,E15=0),"",IF(D15=0,1/C15,N(AD15)/E15)) | BD15: =IF(OR(C15="",BD$2>C15,E15=0),"",IF(D15=0,1/C15,N(AE15)/E15)) | BE15: =IF(OR(C15="",BE$2>C15,E15=0),"",IF(D15=0,1/C15,N(AF15)/E15)) | BF15: =IF(C15="","",SUM(AH15:BE15))
A16: 11 | B16: =IF(Projects!B16="","",Projects!B16) | C16: =IF(Projects!E16="","",Projects!E16) | D16: =COUNT($I16:$AF16) -> 0 | E16: =IF(C16="",0,IF(D16=0,C16,SUMPRODUCT($I16:$AF16*($I$2:$AF$2<=C16)))) -> 0 | F16: =IF(OR(C16="",Projects!D16=""),1,MAX(1,((YEAR(Projects!$C$2)-YEAR(Projects!D16))*12+MONTH(Projects!$C$2)-MONTH(Projects!D16)+1)+1)) -> 1 | G16: =IF(C16="",0,IF(D16=0,MAX(0,C16-F16+1),SUMPRODUCT($I16:$AF16*($I$2:$AF$2>=F16)*($I$2:$AF$2<=C16)))) -> 0 | H16: =IF(C16="",0,SUMPRODUCT(($I16:$AF16<>0)*($I$2:$AF$2>C16))) -> 0 | AH16: =IF(OR(C16="",AH$2>C16,E16=0),"",IF(D16=0,1/C16,N(I16)/E16)) | AI16: =IF(OR(C16="",AI$2>C16,E16=0),"",IF(D16=0,1/C16,N(J16)/E16)) | AJ16: =IF(OR(C16="",AJ$2>C16,E16=0),"",IF(D16=0,1/C16,N(K16)/E16)) | AK16: =IF(OR(C16="",AK$2>C16,E16=0),"",IF(D16=0,1/C16,N(L16)/E16)) | AL16: =IF(OR(C16="",AL$2>C16,E16=0),"",IF(D16=0,1/C16,N(M16)/E16)) | AM16: =IF(OR(C16="",AM$2>C16,E16=0),"",IF(D16=0,1/C16,N(N16)/E16)) | AN16: =IF(OR(C16="",AN$2>C16,E16=0),"",IF(D16=0,1/C16,N(O16)/E16)) | AO16: =IF(OR(C16="",AO$2>C16,E16=0),"",IF(D16=0,1/C16,N(P16)/E16)) | AP16: =IF(OR(C16="",AP$2>C16,E16=0),"",IF(D16=0,1/C16,N(Q16)/E16)) | AQ16: =IF(OR(C16="",AQ$2>C16,E16=0),"",IF(D16=0,1/C16,N(R16)/E16)) | AR16: =IF(OR(C16="",AR$2>C16,E16=0),"",IF(D16=0,1/C16,N(S16)/E16)) | AS16: =IF(OR(C16="",AS$2>C16,E16=0),"",IF(D16=0,1/C16,N(T16)/E16)) | AT16: =IF(OR(C16="",AT$2>C16,E16=0),"",IF(D16=0,1/C16,N(U16)/E16)) | AU16: =IF(OR(C16="",AU$2>C16,E16=0),"",IF(D16=0,1/C16,N(V16)/E16)) | AV16: =IF(OR(C16="",AV$2>C16,E16=0),"",IF(D16=0,1/C16,N(W16)/E16)) | AW16: =IF(OR(C16="",AW$2>C16,E16=0),"",IF(D16=0,1/C16,N(X16)/E16)) | AX16: =IF(OR(C16="",AX$2>C16,E16=0),"",IF(D16=0,1/C16,N(Y16)/E16)) | AY16: =IF(OR(C16="",AY$2>C16,E16=0),"",IF(D16=0,1/C16,N(Z16)/E16)) | AZ16: =IF(OR(C16="",AZ$2>C16,E16=0),"",IF(D16=0,1/C16,N(AA16)/E16)) | BA16: =IF(OR(C16="",BA$2>C16,E16=0),"",IF(D16=0,1/C16,N(AB16)/E16)) | BB16: =IF(OR(C16="",BB$2>C16,E16=0),"",IF(D16=0,1/C16,N(AC16)/E16)) | BC16: =IF(OR(C16="",BC$2>C16,E16=0),"",IF(D16=0,1/C16,N(AD16)/E16)) | BD16: =IF(OR(C16="",BD$2>C16,E16=0),"",IF(D16=0,1/C16,N(AE16)/E16)) | BE16: =IF(OR(C16="",BE$2>C16,E16=0),"",IF(D16=0,1/C16,N(AF16)/E16)) | BF16: =IF(C16="","",SUM(AH16:BE16))
A17: 12 | B17: =IF(Projects!B17="","",Projects!B17) | C17: =IF(Projects!E17="","",Projects!E17) | D17: =COUNT($I17:$AF17) -> 0 | E17: =IF(C17="",0,IF(D17=0,C17,SUMPRODUCT($I17:$AF17*($I$2:$AF$2<=C17)))) -> 0 | F17: =IF(OR(C17="",Projects!D17=""),1,MAX(1,((YEAR(Projects!$C$2)-YEAR(Projects!D17))*12+MONTH(Projects!$C$2)-MONTH(Projects!D17)+1)+1)) -> 1 | G17: =IF(C17="",0,IF(D17=0,MAX(0,C17-F17+1),SUMPRODUCT($I17:$AF17*($I$2:$AF$2>=F17)*($I$2:$AF$2<=C17)))) -> 0 | H17: =IF(C17="",0,SUMPRODUCT(($I17:$AF17<>0)*($I$2:$AF$2>C17))) -> 0 | AH17: =IF(OR(C17="",AH$2>C17,E17=0),"",IF(D17=0,1/C17,N(I17)/E17)) | AI17: =IF(OR(C17="",AI$2>C17,E17=0),"",IF(D17=0,1/C17,N(J17)/E17)) | AJ17: =IF(OR(C17="",AJ$2>C17,E17=0),"",IF(D17=0,1/C17,N(K17)/E17)) | AK17: =IF(OR(C17="",AK$2>C17,E17=0),"",IF(D17=0,1/C17,N(L17)/E17)) | AL17: =IF(OR(C17="",AL$2>C17,E17=0),"",IF(D17=0,1/C17,N(M17)/E17)) | AM17: =IF(OR(C17="",AM$2>C17,E17=0),"",IF(D17=0,1/C17,N(N17)/E17)) | AN17: =IF(OR(C17="",AN$2>C17,E17=0),"",IF(D17=0,1/C17,N(O17)/E17)) | AO17: =IF(OR(C17="",AO$2>C17,E17=0),"",IF(D17=0,1/C17,N(P17)/E17)) | AP17: =IF(OR(C17="",AP$2>C17,E17=0),"",IF(D17=0,1/C17,N(Q17)/E17)) | AQ17: =IF(OR(C17="",AQ$2>C17,E17=0),"",IF(D17=0,1/C17,N(R17)/E17)) | AR17: =IF(OR(C17="",AR$2>C17,E17=0),"",IF(D17=0,1/C17,N(S17)/E17)) | AS17: =IF(OR(C17="",AS$2>C17,E17=0),"",IF(D17=0,1/C17,N(T17)/E17)) | AT17: =IF(OR(C17="",AT$2>C17,E17=0),"",IF(D17=0,1/C17,N(U17)/E17)) | AU17: =IF(OR(C17="",AU$2>C17,E17=0),"",IF(D17=0,1/C17,N(V17)/E17)) | AV17: =IF(OR(C17="",AV$2>C17,E17=0),"",IF(D17=0,1/C17,N(W17)/E17)) | AW17: =IF(OR(C17="",AW$2>C17,E17=0),"",IF(D17=0,1/C17,N(X17)/E17)) | AX17: =IF(OR(C17="",AX$2>C17,E17=0),"",IF(D17=0,1/C17,N(Y17)/E17)) | AY17: =IF(OR(C17="",AY$2>C17,E17=0),"",IF(D17=0,1/C17,N(Z17)/E17)) | AZ17: =IF(OR(C17="",AZ$2>C17,E17=0),"",IF(D17=0,1/C17,N(AA17)/E17)) | BA17: =IF(OR(C17="",BA$2>C17,E17=0),"",IF(D17=0,1/C17,N(AB17)/E17)) | BB17: =IF(OR(C17="",BB$2>C17,E17=0),"",IF(D17=0,1/C17,N(AC17)/E17)) | BC17: =IF(OR(C17="",BC$2>C17,E17=0),"",IF(D17=0,1/C17,N(AD17)/E17)) | BD17: =IF(OR(C17="",BD$2>C17,E17=0),"",IF(D17=0,1/C17,N(AE17)/E17)) | BE17: =IF(OR(C17="",BE$2>C17,E17=0),"",IF(D17=0,1/C17,N(AF17)/E17)) | BF17: =IF(C17="","",SUM(AH17:BE17))
A18: 13 | B18: =IF(Projects!B18="","",Projects!B18) | C18: =IF(Projects!E18="","",Projects!E18) | D18: =COUNT($I18:$AF18) -> 0 | E18: =IF(C18="",0,IF(D18=0,C18,SUMPRODUCT($I18:$AF18*($I$2:$AF$2<=C18)))) -> 0 | F18: =IF(OR(C18="",Projects!D18=""),1,MAX(1,((YEAR(Projects!$C$2)-YEAR(Projects!D18))*12+MONTH(Projects!$C$2)-MONTH(Projects!D18)+1)+1)) -> 1 | G18: =IF(C18="",0,IF(D18=0,MAX(0,C18-F18+1),SUMPRODUCT($I18:$AF18*($I$2:$AF$2>=F18)*($I$2:$AF$2<=C18)))) -> 0 | H18: =IF(C18="",0,SUMPRODUCT(($I18:$AF18<>0)*($I$2:$AF$2>C18))) -> 0 | AH18: =IF(OR(C18="",AH$2>C18,E18=0),"",IF(D18=0,1/C18,N(I18)/E18)) | AI18: =IF(OR(C18="",AI$2>C18,E18=0),"",IF(D18=0,1/C18,N(J18)/E18)) | AJ18: =IF(OR(C18="",AJ$2>C18,E18=0),"",IF(D18=0,1/C18,N(K18)/E18)) | AK18: =IF(OR(C18="",AK$2>C18,E18=0),"",IF(D18=0,1/C18,N(L18)/E18)) | AL18: =IF(OR(C18="",AL$2>C18,E18=0),"",IF(D18=0,1/C18,N(M18)/E18)) | AM18: =IF(OR(C18="",AM$2>C18,E18=0),"",IF(D18=0,1/C18,N(N18)/E18)) | AN18: =IF(OR(C18="",AN$2>C18,E18=0),"",IF(D18=0,1/C18,N(O18)/E18)) | AO18: =IF(OR(C18="",AO$2>C18,E18=0),"",IF(D18=0,1/C18,N(P18)/E18)) | AP18: =IF(OR(C18="",AP$2>C18,E18=0),"",IF(D18=0,1/C18,N(Q18)/E18)) | AQ18: =IF(OR(C18="",AQ$2>C18,E18=0),"",IF(D18=0,1/C18,N(R18)/E18)) | AR18: =IF(OR(C18="",AR$2>C18,E18=0),"",IF(D18=0,1/C18,N(S18)/E18)) | AS18: =IF(OR(C18="",AS$2>C18,E18=0),"",IF(D18=0,1/C18,N(T18)/E18)) | AT18: =IF(OR(C18="",AT$2>C18,E18=0),"",IF(D18=0,1/C18,N(U18)/E18)) | AU18: =IF(OR(C18="",AU$2>C18,E18=0),"",IF(D18=0,1/C18,N(V18)/E18)) | AV18: =IF(OR(C18="",AV$2>C18,E18=0),"",IF(D18=0,1/C18,N(W18)/E18)) | AW18: =IF(OR(C18="",AW$2>C18,E18=0),"",IF(D18=0,1/C18,N(X18)/E18)) | AX18: =IF(OR(C18="",AX$2>C18,E18=0),"",IF(D18=0,1/C18,N(Y18)/E18)) | AY18: =IF(OR(C18="",AY$2>C18,E18=0),"",IF(D18=0,1/C18,N(Z18)/E18)) | AZ18: =IF(OR(C18="",AZ$2>C18,E18=0),"",IF(D18=0,1/C18,N(AA18)/E18)) | BA18: =IF(OR(C18="",BA$2>C18,E18=0),"",IF(D18=0,1/C18,N(AB18)/E18)) | BB18: =IF(OR(C18="",BB$2>C18,E18=0),"",IF(D18=0,1/C18,N(AC18)/E18)) | BC18: =IF(OR(C18="",BC$2>C18,E18=0),"",IF(D18=0,1/C18,N(AD18)/E18)) | BD18: =IF(OR(C18="",BD$2>C18,E18=0),"",IF(D18=0,1/C18,N(AE18)/E18)) | BE18: =IF(OR(C18="",BE$2>C18,E18=0),"",IF(D18=0,1/C18,N(AF18)/E18)) | BF18: =IF(C18="","",SUM(AH18:BE18))
... A55: 50 | B55: =IF(Projects!B55="","",Projects!B55) | C55: =IF(Projects!E55="","",Projects!E55) | D55: =COUNT($I55:$AF55) -> 0 | E55: =IF(C55="",0,IF(D55=0,C55,SUMPRODUCT($I55:$AF55*($I$2:$AF$2<=C55)))) -> 0 | F55: =IF(OR(C55="",Projects!D55=""),1,MAX(1,((YEAR(Projects!$C$2)-YEAR(Projects!D55))*12+MONTH(Projects!$C$2)-MONTH(Projects!D55)+1)+1)) -> 1 | G55: =IF(C55="",0,IF(D55=0,MAX(0,C55-F55+1),SUMPRODUCT($I55:$AF55*($I$2:$AF$2>=F55)*($I$2:$AF$2<=C55)))) -> 0 | H55: =IF(C55="",0,SUMPRODUCT(($I55:$AF55<>0)*($I$2:$AF$2>C55))) -> 0 | AH55: =IF(OR(C55="",AH$2>C55,E55=0),"",IF(D55=0,1/C55,N(I55)/E55)) | AI55: =IF(OR(C55="",AI$2>C55,E55=0),"",IF(D55=0,1/C55,N(J55)/E55)) | AJ55: =IF(OR(C55="",AJ$2>C55,E55=0),"",IF(D55=0,1/C55,N(K55)/E55)) | AK55: =IF(OR(C55="",AK$2>C55,E55=0),"",IF(D55=0,1/C55,N(L55)/E55)) | AL55: =IF(OR(C55="",AL$2>C55,E55=0),"",IF(D55=0,1/C55,N(M55)/E55)) | AM55: =IF(OR(C55="",AM$2>C55,E55=0),"",IF(D55=0,1/C55,N(N55)/E55)) | AN55: =IF(OR(C55="",AN$2>C55,E55=0),"",IF(D55=0,1/C55,N(O55)/E55)) | AO55: =IF(OR(C55="",AO$2>C55,E55=0),"",IF(D55=0,1/C55,N(P55)/E55)) | AP55: =IF(OR(C55="",AP$2>C55,E55=0),"",IF(D55=0,1/C55,N(Q55)/E55)) | AQ55: =IF(OR(C55="",AQ$2>C55,E55=0),"",IF(D55=0,1/C55,N(R55)/E55)) | AR55: =IF(OR(C55="",AR$2>C55,E55=0),"",IF(D55=0,1/C55,N(S55)/E55)) | AS55: =IF(OR(C55="",AS$2>C55,E55=0),"",IF(D55=0,1/C55,N(T55)/E55)) | AT55: =IF(OR(C55="",AT$2>C55,E55=0),"",IF(D55=0,1/C55,N(U55)/E55)) | AU55: =IF(OR(C55="",AU$2>C55,E55=0),"",IF(D55=0,1/C55,N(V55)/E55)) | AV55: =IF(OR(C55="",AV$2>C55,E55=0),"",IF(D55=0,1/C55,N(W55)/E55)) | AW55: =IF(OR(C55="",AW$2>C55,E55=0),"",IF(D55=0,1/C55,N(X55)/E55)) | AX55: =IF(OR(C55="",AX$2>C55,E55=0),"",IF(D55=0,1/C55,N(Y55)/E55)) | AY55: =IF(OR(C55="",AY$2>C55,E55=0),"",IF(D55=0,1/C55,N(Z55)/E55)) | AZ55: =IF(OR(C55="",AZ$2>C55,E55=0),"",IF(D55=0,1/C55,N(AA55)/E55)) | BA55: =IF(OR(C55="",BA$2>C55,E55=0),"",IF(D55=0,1/C55,N(AB55)/E55)) | BB55: =IF(OR(C55="",BB$2>C55,E55=0),"",IF(D55=0,1/C55,N(AC55)/E55)) | BC55: =IF(OR(C55="",BC$2>C55,E55=0),"",IF(D55=0,1/C55,N(AD55)/E55)) | BD55: =IF(OR(C55="",BD$2>C55,E55=0),"",IF(D55=0,1/C55,N(AE55)/E55)) | BE55: =IF(OR(C55="",BE$2>C55,E55=0),"",IF(D55=0,1/C55,N(AF55)/E55)) | BF55: =IF(C55="","",SUM(AH55:BE55))

Sheet WIP Log
A1: WIP Log (monthly actuals)
A3: Enter the WIP actual for each project and month. Only months up to and including the Current Month count; later months are ignored.
D4: =IF(D5<=Projects!$C$2,"actual","future") -> actual | E4: =IF(E5<=Projects!$C$2,"actual","future") -> actual | F4: =IF(F5<=Projects!$C$2,"actual","future") -> actual | G4: =IF(G5<=Projects!$C$2,"actual","future") -> actual | H4: =IF(H5<=Projects!$C$2,"actual","future") -> actual | I4: =IF(I5<=Projects!$C$2,"actual","future") -> actual | J4: =IF(J5<=Projects!$C$2,"actual","future") -> actual | K4: =IF(K5<=Projects!$C$2,"actual","future") -> actual | ... AM4: =IF(AM5<=Projects!$C$2,"actual","future") -> future
A5: # | B5: Project Name | C5: WIP to Date (≤ Current Month) | D5: =Projects!$C$3 -> 46023 | E5: =EDATE(D5,1) -> 46054 | F5: =EDATE(E5,1) -> 46082 | G5: =EDATE(F5,1) -> 46113 | H5: =EDATE(G5,1) -> 46143 | I5: =EDATE(H5,1) -> 46174 | J5: =EDATE(I5,1) -> 46204 | K5: =EDATE(J5,1) -> 46235 | L5: =EDATE(K5,1) -> 46266 | ... AM5: =EDATE(AL5,1) -> 47088
A6: 1 | B6: =IF(Projects!B6="","",Projects!B6) -> Example Project (slide) | C6: =SUMPRODUCT($D6:$AM6*($D$5:$AM$5<=Projects!$C$2)) -> 1000 | M6: 1000
A7: 2 | B7: =IF(Projects!B7="","",Projects!B7) | C7: =SUMPRODUCT($D7:$AM7*($D$5:$AM$5<=Projects!$C$2)) -> 0
A8: 3 | B8: =IF(Projects!B8="","",Projects!B8) | C8: =SUMPRODUCT($D8:$AM8*($D$5:$AM$5<=Projects!$C$2)) -> 0
A9: 4 | B9: =IF(Projects!B9="","",Projects!B9) | C9: =SUMPRODUCT($D9:$AM9*($D$5:$AM$5<=Projects!$C$2)) -> 0
A10: 5 | B10: =IF(Projects!B10="","",Projects!B10) | C10: =SUMPRODUCT($D10:$AM10*($D$5:$AM$5<=Projects!$C$2)) -> 0
A11: 6 | B11: =IF(Projects!B11="","",Projects!B11) | C11: =SUMPRODUCT($D11:$AM11*($D$5:$AM$5<=Projects!$C$2)) -> 0
A12: 7 | B12: =IF(Projects!B12="","",Projects!B12) | C12: =SUMPRODUCT($D12:$AM12*($D$5:$AM$5<=Projects!$C$2)) -> 0
A13: 8 | B13: =IF(Projects!B13="","",Projects!B13) | C13: =SUMPRODUCT($D13:$AM13*($D$5:$AM$5<=Projects!$C$2)) -> 0
A14: 9 | B14: =IF(Projects!B14="","",Projects!B14) | C14: =SUMPRODUCT($D14:$AM14*($D$5:$AM$5<=Projects!$C$2)) -> 0
A15: 10 | B15: =IF(Projects!B15="","",Projects!B15) | C15: =SUMPRODUCT($D15:$AM15*($D$5:$AM$5<=Projects!$C$2)) -> 0
A16: 11 | B16: =IF(Projects!B16="","",Projects!B16) | C16: =SUMPRODUCT($D16:$AM16*($D$5:$AM$5<=Projects!$C$2)) -> 0
A17: 12 | B17: =IF(Projects!B17="","",Projects!B17) | C17: =SUMPRODUCT($D17:$AM17*($D$5:$AM$5<=Projects!$C$2)) -> 0
A18: 13 | B18: =IF(Projects!B18="","",Projects!B18) | C18: =SUMPRODUCT($D18:$AM18*($D$5:$AM$5<=Projects!$C$2)) -> 0
... A55: 50 | B55: =IF(Projects!B55="","",Projects!B55) | C55: =SUMPRODUCT($D55:$AM55*($D$5:$AM$5<=Projects!$C$2)) -> 0
B57: TOTAL | C57: =SUM(C6:C55) -> 1000 | D57: =SUM(D6:D55) -> 0 | E57: =SUM(E6:E55) -> 0 | F57: =SUM(F6:F55) -> 0 | G57: =SUM(G6:G55) -> 0 | H57: =SUM(H6:H55) -> 0 | I57: =SUM(I6:I55) -> 0 | J57: =SUM(J6:J55) -> 0 | ... AM57: =SUM(AM6:AM55) -> 0

Sheet Project Page
A1: Project Page | J1: row | K1: =IFERROR(MATCH(B3,Projects!$B$6:$B$55,0),0) -> 1
A3: Select project ▸ | B3: Example Project (slide) | F3: =IF(ISNA(MATCH(B3,Projects!$B$6:$B$55,0)),"◂ Pick a project from the dropdown","")
A5: Engagement Manager | B5: =IF($K$1=0,"",INDEX(Projects!$C$6:$C$55,$K$1)&"") -> J. Doe
A6: Starting Month | B6: =IF($K$1=0,"",INDEX(Projects!$D$6:$D$55,$K$1)) -> 46296
A7: Duration (months) | B7: =IF($K$1=0,"",INDEX(Projects!$E$6:$E$55,$K$1)) -> 5
A8: End Month | B8: =IF($K$1=0,"",INDEX(Projects!$F$6:$F$55,$K$1)) -> 46419
A9: Contracted Budget | B9: =IF($K$1=0,"",INDEX(Projects!$G$6:$G$55,$K$1)) -> 10000
A10: WIP to Date | B10: =IF($K$1=0,"",INDEX(Projects!$H$6:$H$55,$K$1)) -> 1000
A11: Budgeted (Contract − WIP) | B11: =IF($K$1=0,"",INDEX(Projects!$I$6:$I$55,$K$1)) -> 9000
A12: Remaining Months | B12: =IF($K$1=0,"",INDEX(Projects!$J$6:$J$55,$K$1)) -> 4
A13: Status | B13: =IF($K$1=0,"",INDEX(Projects!$N$6:$N$55,$K$1)&"") -> OK
A16: Project Month | B16: Calendar Month | C16: Raw Weight | D16: Plan Weight (Σ=1) | E16: Original Plan (Contract × weight) | F16: WIP Actual | G16: Phased Budgeted | H16: Total (WIP + Phased) | I16: Actual / Forecast
A17: =IF(AND($K$1>0,1<=N($B$7)),1,"") -> 1 | B17: =IF(A17="","",EDATE($B$6,A17-1)) -> 46296 | C17: =IF(A17="","",IF(INDEX(Phasing!$D$6:$D$55,$K$1)=0,1,N(INDEX(Phasing!$I$6:$AF$55,$K$1,A17)))) -> 1 | D17: =IF(A17="","",N(INDEX(Phasing!$AH$6:$BE$55,$K$1,A17))) -> 0.11111111 | E17: =IF(A17="","",D17*N($B$9)) -> 1111.1111 | F17: =IF(A17="","",IF(AND(AND(((YEAR(B17)-YEAR(Projects!$C$3))*12+MONTH(B17)-MONTH(Projects!$C$3)+1)>=1,((YEAR(B17)-YEAR(Projects!$C$3))*12+MONTH(B17)-MONTH(Projects!$C$3)+1)<=36),B17<=Projects!$C$2),INDEX('WIP Log'!$D$6:$AM$55,$K$1,((YEAR(B17)-YEAR(Projects!$C$3))*12+MONTH(B17)-MONTH(Projects!$C$3)+1)),0)) -> 1000 | G17: =IF(A17="","",IF(AND(((YEAR(B17)-YEAR(Projects!$C$3))*12+MONTH(B17)-MONTH(Projects!$C$3)+1)>=1,((YEAR(B17)-YEAR(Projects!$C$3))*12+MONTH(B17)-MONTH(Projects!$C$3)+1)<=36),INDEX('Phased Budget'!$H$6:$AQ$55,$K$1,((YEAR(B17)-YEAR(Projects!$C$3))*12+MONTH(B17)-MONTH(Projects!$C$3)+1)),0)) -> 0 | H17: =IF(A17="","",F17+G17) -> 1000 | I17: =IF(A17="","",IF(B17<=Projects!$C$2,"Actual","Forecast")) -> Actual
